Workbook

Sheet 附件1
A1: 西藏自治区察隅县帮扶资金统计及使用情况汇总表 （截至2026年6月20日数据）
A2: 序号 | B2: 地市名称 | C2: 县区名称 | D2: 帮扶资金使用情况（万元） （保留小数点后面2位）
D3: 合计 | E3: 第一阶段 （包括2013年至2015年使用的各级财政专项扶贫资金、援藏资金、定点帮扶资金、地方政府债券资金、社会捐赠资金） | H3: 第二阶段 （包括2016年至2020年使用的各级财政涉农统筹整合资金（专项扶贫资金）、援藏资金、定点帮扶资金、地方政府债券资金、社会捐赠资金） | K3: 第三阶段 （包括2021年至2023年使用的各级财政衔接推进乡村振兴补助资金、涉农统筹整合资金（县级）、援藏资金、定点帮扶资金、地方政府债券资金、社会捐赠资金）
E4: 小计 | F4: 形成资产类 | G4: 未形成资产类 | H4: 小计 | I4: 形成资产类 | J4: 未形成资产类 | K4: 小计 | L4: 形成资产类 | M4: 未形成资产类
A5: 填表说明： | D5: 应为该县（区）所有帮扶资金总数 | E5: 应为该县（区）2013年至2015年帮扶资金小计数 | F5: 帮扶资金在使用过程中形成固定资产、权益类资产、生物性资产、低值易耗品、无形资产等的所有项目实际投入资金总数 | G5: 帮扶资金在使用过程中未形成资产的所有项目实际投入资金总数 | H5: 应为该县（区）2016年至2020年帮扶资金小计数 | I5: 帮扶资金在使用过程中形成固定资产、权益类资产、生物性资产、低值易耗品、无形资产等的所有项目实际投入资金总数 | J5: 帮扶资金在使用过程中未形成资产的所有项目实际投入资金总数 | K5: 应为该县（区）2021年至2023年帮扶资金小计数 | L5: 帮扶资金在使用过程中形成固定资产、权益类资产、生物性资产、低值易耗品、无形资产等的所有项目实际投入资金总数 | M5: 帮扶资金在使用过程中未形成资产的所有项目实际投入资金总数
A6: 1 | B6: 林芝市 | C6: 察隅县 | D6: =(E6+H6+K6) -> 324637.59 | E6: =(F6+G6) -> 19872.425 | F6: =198724250.74/10000 -> 19872.425 | G6: 0 | H6: =(I6+J6) -> 199879.74 | I6: =1837192850.72528/10000 -> 183719.29 | J6: =161604500/10000 -> 16160.45 | K6: =(L6+M6) -> 104885.43 | L6: =988974809.04/10000 -> 98897.481 | M6: =59879520/10000 -> 5987.952

Sheet 附件2
A1: 西藏自治区察隅县帮扶项目清单 （截至2026年6月30日数据）
A2: 序号 | B2: 地市名称 | C2: 县区名称 | D2: 项目年度 | E2: 项目名称 | F2: 是否为为形成资产项目 | G2: 是否为帮扶产业项目 | H2: 帮扶项目资金批复情况（元） | AG2: 帮扶项目资金使用情况（元） | BF2: 是否已确权 | BG2: 资料来源类型 | BH2: 项目申报主体
H3: 合计 | I3: 政策性资金 | AF3: 其他渠道资金（如企业自筹、信贷资金等非政策性资金） | AG3: 合计 | AH3: 政策性资金 | BE3: 其他渠道资金（如企业自筹、信贷资金等非政策性资金）
I4: 政策性资金小计 | J4: 专项扶贫资金 | O4: 统筹整合涉农资金 | T4: 财政衔接推进乡村振兴 补助资金 | Y4: 援藏资金 | AC4: 定点帮扶资金 | AD4: 地方政府债劵资金 | AE4: 社会捐赠（财政入账） | AH4: 政策性资金小计 | AI4: 专项扶贫资金 | AN4: 统筹整合涉农资金 | AS4: 财政衔接推进乡村振兴 补助资金 | AX4: 援藏资金 | BB4: 定点帮扶资金 | BC4: 地方政府债劵资金 | BD4: 社会捐赠（财政入账）
J5: 小计 | K5: 中央 | L5: 省级 | M5: 市级 | N5: 县级 | O5: 小计 | P5: 中央 | Q5: 省级 | R5: 市级 | S5: 县级 | T5: 小计 | U5: 中央 | V5: 省级 | W5: 市级 | X5: 县级 | Y5: 小计 | Z5: 省级 | AA5: 市级 | AB5: 县级 | AI5: 小计 | AJ5: 中央 | AK5: 省级 | AL5: 市级 | AM5: 县级 | AN5: 小计 | AO5: 中央 | AP5: 省级 | AQ5: 市级 | AR5: 县级 | AS5: 小计 | AT5: 中央 | AU5: 省级 | AV5: 市级 | AW5: 县级 | AX5: 小计 | AY5: 省级 | AZ5: 市级 | BA5: 县级
A6: 填表说明： | D6: 以项目批复中批复年度为准 | E6: 以项目批复中项目名称为准 | F6: 在“是/否”中选择 | G6: 在“是/否”中选择 | J6: 以项目批复中项目计划投资总金额为准 （保留小数点后面2位） | AH6: 该数据与附表1形成资产类金额数据一致 | AI6: 以项目竣工决算中核算实际投资金额为准 （保留小数点后面2位） | BF6: 在“是/否”中选择 | BG6: 财评、合同、立项等
A7: 合计 | H7: =SUM(H8:H602) -> 3.2856581e+09 | I7: =SUM(I8:I602) -> 3.2533117e+09 | J7: =SUM(J8:J602) -> 2.1904187e+08 | K7: =SUM(K8:K602) -> 89403700 | L7: =SUM(L8:L602) -> 15300000 | M7: =SUM(M8:M602) -> 86495000 | N7: =SUM(N8:N602) -> 27843169 | O7: =SUM(O8:O602) -> 1.1710255e+09 | ... BE7: =SUM(BE8:BE602) -> 25822939
A8: 1 | B8: 林芝市 | C8: 察隅县 | D8: 2017 | E8: 察隅县察瓦龙乡汽修市场建设项目 | F8: 是 | G8: 是 | H8: =I8+AF8 -> 13832800 | I8: =O8+J8+T8+Y8+AE8+AC8+AD8 -> 13832800 | J8: =N8+M8+L8+K8 -> 0 | O8: =S8+R8+Q8+P8 -> 13832800 | Q8: 13832800 | T8: =U8+V8+W8+X8 -> 0 | Y8: =AA8+Z8+AB8 -> 0 | AG8: =AH8+BE8 -> 13081530 | AH8: =AN8+AI8+AS8+AX8+BD8+BB8+BC8 -> 13081530 | AI8: =AM8+AL8+AK8+AJ8 -> 0 | AN8: =AR8+AQ8+AP8+AO8 -> 13081530 | AP8: 13081530 | AS8: =AW8+AV8+AU8+AT8 -> 0 | AX8: =AZ8+AY8+BA8 -> 0 | BE8: 0 | BF8: 是 | BG8: 确权资料
A9: 2 | B9: 林芝市 | C9: 察隅县 | D9: 2017 | E9: 察隅县下察隅镇布巴村等三个行政村猕猴桃种植建设项目 | F9: 是 | G9: 是 | H9: =I9+AF9 -> 21304200 | I9: =O9+J9+T9+Y9+AE9+AC9+AD9 -> 14843900 | J9: =N9+M9+L9+K9 -> 0 | O9: =S9+R9+Q9+P9 -> 14843900 | S9: 14843900 | T9: =U9+V9+W9+X9 -> 0 | Y9: =AA9+Z9+AB9 -> 0 | AF9: 6460300 | AG9: =AH9+BE9 -> 21009370 | AH9: =AN9+AI9+AS9+AX9+BD9+BB9+BC9 -> 14843900 | AI9: =AM9+AL9+AK9+AJ9 -> 0 | AN9: =AR9+AQ9+AP9+AO9 -> 14843900 | AR9: 14843900 | AS9: =AW9+AV9+AU9+AT9 -> 0 | AX9: =AZ9+AY9+BA9 -> 0 | BE9: =21009369.65-AH9 -> 6165469.7 | BF9: 否 | BG9: 只有电子数据，来源超1000万财评，2019年
A10: 3 | B10: 林芝市 | C10: 察隅县 | D10: 2018 | E10: 察隅县察瓦龙乡岗藏村机耕道建设项目 | F10: 是 | G10: 否 | H10: =I10+AF10 -> 361600 | I10: =O10+J10+T10+Y10+AE10+AC10+AD10 -> 361600 | J10: =N10+M10+L10+K10 -> 0 | O10: =S10+R10+Q10+P10 -> 361600 | S10: 361600 | T10: =U10+V10+W10+X10 -> 0 | Y10: =AA10+Z10+AB10 -> 0 | AG10: =AH10+BE10 -> 356668 | AH10: =AN10+AI10+AS10+AX10+BD10+BB10+BC10 -> 356668 | AI10: =AM10+AL10+AK10+AJ10 -> 0 | AN10: =AR10+AQ10+AP10+AO10 -> 356668 | AR10: 356668 | AS10: =AW10+AV10+AU10+AT10 -> 0 | AX10: =AZ10+AY10+BA10 -> 0 | BF10: 是 | BG10: 确权资料，确权金额和台账审定金额一致，有支付凭证 | BH10: 察隅县脱贫攻坚指挥部综合组
A11: 4 | B11: 林芝市 | C11: 察隅县 | D11: 2018 | E11: 察隅县下察隅镇共同村阿美组易地扶贫搬迁安置项目 | F11: 是 | G11: 否 | H11: =I11+AF11 -> 9922100 | I11: =O11+J11+T11+Y11+AE11+AC11+AD11 -> 9922100 | J11: =N11+M11+L11+K11 -> 0 | O11: =S11+R11+Q11+P11 -> 0 | T11: =U11+V11+W11+X11 -> 0 | Y11: =AA11+Z11+AB11 -> 9922100 | AA11: 9922100 | AG11: =AH11+BE11 -> 9787823.5 | AH11: =AN11+AI11+AS11+AX11+BD11+BB11+BC11 -> 9787823.5 | AI11: =AM11+AL11+AK11+AJ11 -> 0 | AN11: =AR11+AQ11+AP11+AO11 -> 0 | AS11: =AW11+AV11+AU11+AT11 -> 0 | AX11: =AZ11+AY11+BA11 -> 9787823.5 | AZ11: 9787823.5 | BF11: 否 | BG11: 立项批复+50-1000万台账 | BH11: 县安居办
A12: 5 | B12: 林芝市 | C12: 察隅县 | D12: 2019 | E12: 察隅县竹瓦根镇沙通坝建材市场建设项目 | F12: 是 | G12: 是 | H12: =I12+AF12 -> 24760000 | I12: =O12+J12+T12+Y12+AE12+AC12+AD12 -> 24760000 | J12: =N12+M12+L12+K12 -> 0 | O12: =S12+R12+Q12+P12 -> 24760000 | P12: 24760000 | T12: =U12+V12+W12+X12 -> 0 | Y12: =AA12+Z12+AB12 -> 0 | AG12: =AH12+BE12 -> 23047426 | AH12: =AN12+AI12+AS12+AX12+BD12+BB12+BC12 -> 23047426 | AI12: =AM12+AL12+AK12+AJ12 -> 0 | AN12: =AR12+AQ12+AP12+AO12 -> 23047426 | AO12: 23047426 | AS12: =AW12+AV12+AU12+AT12 -> 0 | AX12: =AZ12+AY12+BA12 -> 0 | BE12: 0 | BF12: 是 | BG12: 确权资料+超过1千万的财评台账（21年）
A13: 6 | B13: 林芝市 | C13: 察隅县 | D13: 2019 | E13: 察隅县古拉乡石榴种植项目 | F13: 是 | G13: 是 | H13: =I13+AF13 -> 500000 | I13: =O13+J13+T13+Y13+AE13+AC13+AD13 -> 500000 | J13: =N13+M13+L13+K13 -> 0 | O13: =S13+R13+Q13+P13 -> 500000 | Q13: 500000 | T13: =U13+V13+W13+X13 -> 0 | Y13: =AA13+Z13+AB13 -> 0 | AG13: =AH13+BE13 -> 500000 | AH13: =AN13+AI13+AS13+AX13+BD13+BB13+BC13 -> 500000 | AI13: =AM13+AL13+AK13+AJ13 -> 0 | AN13: =AR13+AQ13+AP13+AO13 -> 500000 | AP13: 500000 | AS13: =AW13+AV13+AU13+AT13 -> 0 | AX13: =AZ13+AY13+BA13 -> 0 | BE13: 0 | BF13: 是 | BG13: 确权资料 | BH13: 古拉乡人民政府
A14: 7 | B14: 林芝市 | C14: 察隅县 | D14: 2019 | E14: 察隅县竹瓦根镇生猪养殖项目 | F14: 是 | G14: 是 | H14: =I14+AF14 -> 500000 | I14: =O14+J14+T14+Y14+AE14+AC14+AD14 -> 500000 | J14: =N14+M14+L14+K14 -> 0 | O14: =S14+R14+Q14+P14 -> 500000 | Q14: 500000 | T14: =U14+V14+W14+X14 -> 0 | Y14: =AA14+Z14+AB14 -> 0 | AG14: =AH14+BE14 -> 500000 | AH14: =AN14+AI14+AS14+AX14+BD14+BB14+BC14 -> 500000 | AI14: =AM14+AL14+AK14+AJ14 -> 0 | AN14: =AR14+AQ14+AP14+AO14 -> 500000 | AP14: 500000 | AS14: =AW14+AV14+AU14+AT14 -> 0 | AX14: =AZ14+AY14+BA14 -> 0 | BE14: 0 | BF14: 是 | BG14: 确权资料
A15: 8 | B15: 林芝市 | C15: 察隅县 | D15: 2019 | E15: 察隅县本土生态农产品加工项目 | F15: 是 | G15: 是 | H15: =I15+AF15 -> 2500000 | I15: =O15+J15+T15+Y15+AE15+AC15+AD15 -> 2500000 | J15: =N15+M15+L15+K15 -> 0 | O15: =S15+R15+Q15+P15 -> 2500000 | P15: 1787800 | Q15: 712200 | T15: =U15+V15+W15+X15 -> 0 | Y15: =AA15+Z15+AB15 -> 0 | AG15: =AH15+BE15 -> 2399270.3 | AH15: =AN15+AI15+AS15+AX15+BD15+BB15+BC15 -> 2399270.3 | AI15: =AM15+AL15+AK15+AJ15 -> 0 | AN15: =AR15+AQ15+AP15+AO15 -> 2399270.3 | AO15: 1687070.3 | AP15: 712200 | AS15: =AW15+AV15+AU15+AT15 -> 0 | AX15: =AZ15+AY15+BA15 -> 0 | BE15: 0 | BF15: 是 | BG15: 确权资料+50-1000万台账
A16: 9 | B16: 林芝市 | C16: 察隅县 | D16: 2019 | E16: 察隅县察瓦龙乡邓许村机耕道建设项目 | F16: 是 | G16: 否 | H16: =I16+AF16 -> 731100 | I16: =O16+J16+T16+Y16+AE16+AC16+AD16 -> 731100 | J16: =N16+M16+L16+K16 -> 0 | O16: =S16+R16+Q16+P16 -> 731100 | S16: 731100 | T16: =U16+V16+W16+X16 -> 0 | Y16: =AA16+Z16+AB16 -> 0 | AG16: =AH16+BE16 -> 695200 | AH16: =AN16+AI16+AS16+AX16+BD16+BB16+BC16 -> 695200 | AI16: =AM16+AL16+AK16+AJ16 -> 0 | AN16: =AR16+AQ16+AP16+AO16 -> 695200 | AR16: 695200 | AS16: =AW16+AV16+AU16+AT16 -> 0 | AX16: =AZ16+AY16+BA16 -> 0 | BF16: 是 | BG16: 确权资料，需要核定台账695200审定依据，50-1000万里面没有写审定金额 | BH16: 察隅县脱贫攻坚指挥部办公室
A17: 10 | B17: 林芝市 | C17: 察隅县 | D17: 2019 | E17: 察隅县察瓦龙乡洪东村机耕道建设项目 | F17: 是 | G17: 否 | H17: =I17+AF17 -> 203500 | I17: =O17+J17+T17+Y17+AE17+AC17+AD17 -> 203500 | J17: =N17+M17+L17+K17 -> 0 | O17: =S17+R17+Q17+P17 -> 203500 | S17: 203500 | T17: =U17+V17+W17+X17 -> 0 | Y17: =AA17+Z17+AB17 -> 0 | AG17: =AH17+BE17 -> 193600 | AH17: =AN17+AI17+AS17+AX17+BD17+BB17+BC17 -> 193600 | AI17: =AM17+AL17+AK17+AJ17 -> 0 | AN17: =AR17+AQ17+AP17+AO17 -> 193600 | AR17: 193600 | AS17: =AW17+AV17+AU17+AT17 -> 0 | AX17: =AZ17+AY17+BA17 -> 0 | BF17: 是 | BG17: 确权资料（确权金额和台账审定金额一致，但是没有支付财评） | BH17: 县脱贫攻坚指挥部办公室（扶贫办）
A18: 11 | B18: 林芝市 | C18: 察隅县 | D18: 2019 | E18: 察隅县察瓦龙乡康然村等村组道路建设项目 | F18: 是 | G18: 否 | H18: =I18+AF18 -> 11760200 | I18: =O18+J18+T18+Y18+AE18+AC18+AD18 -> 11760200 | J18: =N18+M18+L18+K18 -> 0 | O18: =S18+R18+Q18+P18 -> 11760200 | P18: 7063200 | Q18: 4697000 | T18: =U18+V18+W18+X18 -> 0 | Y18: =AA18+Z18+AB18 -> 0 | AG18: =AH18+BE18 -> 11541052 | AH18: =AN18+AI18+AS18+AX18+BD18+BB18+BC18 -> 11541052 | AI18: =AM18+AL18+AK18+AJ18 -> 0 | AN18: =AR18+AQ18+AP18+AO18 -> 11541052 | AO18: 7063200 | AP18: 4477851.5 | AS18: =AW18+AV18+AU18+AT18 -> 0 | AX18: =AZ18+AY18+BA18 -> 0 | BF18: 是 | BG18: 确权资料+超过1千万的财评台账（20年） | BH18: 和超过1千万的财评台账20年，记录差1分钱，确权是和台账审定金额一致。
A19: 12 | B19: 林芝市 | C19: 察隅县 | D19: 2019 | E19: 察隅县察瓦龙乡康然村机耕道建设项目 | F19: 是 | G19: 否 | H19: =I19+AF19 -> 1039200 | I19: =O19+J19+T19+Y19+AE19+AC19+AD19 -> 1039200 | J19: =N19+M19+L19+K19 -> 0 | O19: =S19+R19+Q19+P19 -> 1039200 | S19: 1039200 | T19: =U19+V19+W19+X19 -> 0 | Y19: =AA19+Z19+AB19 -> 0 | AG19: =AH19+BE19 -> 970801.92 | AH19: =AN19+AI19+AS19+AX19+BD19+BB19+BC19 -> 970801.92 | AI19: =AM19+AL19+AK19+AJ19 -> 0 | AN19: =AR19+AQ19+AP19+AO19 -> 970801.92 | AR19: 970801.92 | AS19: =AW19+AV19+AU19+AT19 -> 0 | AX19: =AZ19+AY19+BA19 -> 0 | BF19: 是 | BG19: 确权资料+50-1000万台账+财评 | BH19: 察隅县扶贫开发办公室
A20: 13 | B20: 林芝市 | C20: 察隅县 | D20: 2019 | E20: 察隅县察瓦龙乡龙普村机耕道建设项目 | F20: 是 | G20: 否 | H20: =I20+AF20 -> 125700 | I20: =O20+J20+T20+Y20+AE20+AC20+AD20 -> 125700 | J20: =N20+M20+L20+K20 -> 0 | O20: =S20+R20+Q20+P20 -> 125700 | S20: 125700 | T20: =U20+V20+W20+X20 -> 0 | Y20: =AA20+Z20+AB20 -> 0 | AG20: =AH20+BE20 -> 119600 | AH20: =AN20+AI20+AS20+AX20+BD20+BB20+BC20 -> 119600 | AI20: =AM20+AL20+AK20+AJ20 -> 0 | AN20: =AR20+AQ20+AP20+AO20 -> 119600 | AR20: 119600 | AS20: =AW20+AV20+AU20+AT20 -> 0 | AX20: =AZ20+AY20+BA20 -> 0 | BF20: 是 | BG20: 确权资料+立项批复，审定金额来源不明，已经按119600元确权 | BH20: 察隅县扶贫开发办公室
A21: 14 | B21: 林芝市 | C21: 察隅县 | D21: 2019 | E21: 察隅县察瓦龙乡梦扎村机耕道建设项目 | F21: 是 | G21: 否 | H21: =I21+AF21 -> 475000 | I21: =O21+J21+T21+Y21+AE21+AC21+AD21 -> 475000 | J21: =N21+M21+L21+K21 -> 0 | O21: =S21+R21+Q21+P21 -> 475000 | P21: 129695 | S21: 345305 | T21: =U21+V21+W21+X21 -> 0 | Y21: =AA21+Z21+AB21 -> 0 | AG21: =AH21+BE21 -> 451700 | AH21: =AN21+AI21+AS21+AX21+BD21+BB21+BC21 -> 451700 | AI21: =AM21+AL21+AK21+AJ21 -> 0 | AN21: =AR21+AQ21+AP21+AO21 -> 451700 | AO21: 129695 | AR21: 322005 | AS21: =AW21+AV21+AU21+AT21 -> 0 | AX21: =AZ21+AY21+BA21 -> 0 | BF21: 是 | BG21: 确权资料，台账审定金额来源待确定，已经按268900元确权 | BH21: 察隅县扶贫开发办公室
A22: 15 | B22: 林芝市 | C22: 察隅县 | D22: 2019 | E22: 察隅县古拉乡俄玉村过境路段硬化建设项目 | F22: 是 | G22: 否 | H22: =I22+AF22 -> 1046000 | I22: =O22+J22+T22+Y22+AE22+AC22+AD22 -> 1046000 | J22: =N22+M22+L22+K22 -> 0 | O22: =S22+R22+Q22+P22 -> 1046000 | P22: 1046000 | T22: =U22+V22+W22+X22 -> 0 | Y22: =AA22+Z22+AB22 -> 0 | AG22: =AH22+BE22 -> 950604.85 | AH22: =AN22+AI22+AS22+AX22+BD22+BB22+BC22 -> 950604.85 | AI22: =AM22+AL22+AK22+AJ22 -> 0 | AN22: =AR22+AQ22+AP22+AO22 -> 950604.85 | AO22: 950604.85 | AS22: =AW22+AV22+AU22+AT22 -> 0 | AX22: =AZ22+AY22+BA22 -> 0 | BF22: 是 | BG22: 确权资料+50-1000万台账
A23: 16 | B23: 林芝市 | C23: 察隅县 | D23: 2019 | E23: 察隅县古拉乡关龙村二期入户道路建设项目 | F23: 是 | G23: 否 | H23: =I23+AF23 -> 1757800 | I23: =O23+J23+T23+Y23+AE23+AC23+AD23 -> 1757800 | J23: =N23+M23+L23+K23 -> 0 | O23: =S23+R23+Q23+P23 -> 1757800 | P23: 57730 | S23: 1700070 | T23: =U23+V23+W23+X23 -> 0 | Y23: =AA23+Z23+AB23 -> 0 | AG23: =AH23+BE23 -> 1652598.7 | AH23: =AN23+AI23+AS23+AX23+BD23+BB23+BC23 -> 1652598.7 | AI23: =AM23+AL23+AK23+AJ23 -> 0 | AN23: =AR23+AQ23+AP23+AO23 -> 1652598.7 | AO23: 57730 | AR23: 1594868.7 | AS23: =AW23+AV23+AU23+AT23 -> 0 | AX23: =AZ23+AY23+BA23 -> 0 | BF23: 是 | BG23: 确权资料+50-1000万台账 | BH23: 察隅县扶贫开发办公室
A24: 17 | B24: 林芝市 | C24: 察隅县 | D24: 2019 | E24: 察隅县古拉乡南雪村过境路段硬化建设项目 | F24: 是 | G24: 否 | H24: =I24+AF24 -> 653000 | I24: =O24+J24+T24+Y24+AE24+AC24+AD24 -> 653000 | J24: =N24+M24+L24+K24 -> 0 | O24: =S24+R24+Q24+P24 -> 653000 | P24: 653000 | T24: =U24+V24+W24+X24 -> 0 | Y24: =AA24+Z24+AB24 -> 0 | AG24: =AH24+BE24 -> 617709.05 | AH24: =AN24+AI24+AS24+AX24+BD24+BB24+BC24 -> 617709.05 | AI24: =AM24+AL24+AK24+AJ24 -> 0 | AN24: =AR24+AQ24+AP24+AO24 -> 617709.05 | AO24: 617709.05 | AS24: =AW24+AV24+AU24+AT24 -> 0 | AX24: =AZ24+AY24+BA24 -> 0 | BF24: 是 | BG24: 确权资料+50-1000万台账 | BH24: 县交通运输局
A25: 18 | B25: 林芝市 | C25: 察隅县 | D25: 2019 | E25: 察隅县古拉乡特色经济林果种植建设项目 | F25: 是 | G25: 是 | H25: =I25+AF25 -> 9436700 | I25: =O25+J25+T25+Y25+AE25+AC25+AD25 -> 9436700 | J25: =N25+M25+L25+K25 -> 0 | O25: =S25+R25+Q25+P25 -> 9436700 | P25: 9436700 | T25: =U25+V25+W25+X25 -> 0 | Y25: =AA25+Z25+AB25 -> 0 | AG25: =AH25+BE25 -> 8814526.2 | AH25: =AN25+AI25+AS25+AX25+BD25+BB25+BC25 -> 8814526.2 | AI25: =AM25+AL25+AK25+AJ25 -> 0 | AN25: =AR25+AQ25+AP25+AO25 -> 8814526.2 | AO25: 8814526.2 | AS25: =AW25+AV25+AU25+AT25 -> 0 | AX25: =AZ25+AY25+BA25 -> 0 | BE25: 0 | BF25: 是 | BG25: 确权资料
A26: 19 | B26: 林芝市 | C26: 察隅县 | D26: 2019 | E26: 察隅县上察隅镇土地综合治理项目 | F26: 是 | G26: 否 | H26: =I26+AF26 -> 3700000 | I26: =O26+J26+T26+Y26+AE26+AC26+AD26 -> 3700000 | J26: =N26+M26+L26+K26 -> 0 | O26: =S26+R26+Q26+P26 -> 3700000 | Q26: 2383600 | S26: 1316400 | T26: =U26+V26+W26+X26 -> 0 | Y26: =AA26+Z26+AB26 -> 0 | AG26: =AH26+BE26 -> 3395288.4 | AH26: =AN26+AI26+AS26+AX26+BD26+BB26+BC26 -> 3395288.4 | AI26: =AM26+AL26+AK26+AJ26 -> 0 | AN26: =AR26+AQ26+AP26+AO26 -> 3395288.4 | AP26: 2383600 | AR26: 1011688.4 | AS26: =AW26+AV26+AU26+AT26 -> 0 | AX26: =AZ26+AY26+BA26 -> 0 | BF26: 是 | BG26: 确权资料+50-1000万台账
A27: 20 | B27: 林芝市 | C27: 察隅县 | D27: 2019 | E27: 察隅县就业创业孵化基地维修改造工程 | F27: 是 | G27: 是 | H27: =I27+AF27 -> 500000 | I27: =O27+J27+T27+Y27+AE27+AC27+AD27 -> 500000 | J27: =N27+M27+L27+K27 -> 0 | O27: =S27+R27+Q27+P27 -> 500000 | P27: 500000 | T27: =U27+V27+W27+X27 -> 0 | Y27: =AA27+Z27+AB27 -> 0 | AG27: =AH27+BE27 -> 453000 | AH27: =AN27+AI27+AS27+AX27+BD27+BB27+BC27 -> 453000 | AI27: =AM27+AL27+AK27+AJ27 -> 0 | AN27: =AR27+AQ27+AP27+AO27 -> 453000 | AO27: 453000 | AS27: =AW27+AV27+AU27+AT27 -> 0 | AX27: =AZ27+AY27+BA27 -> 0 | BE27: 0 | BF27: 是 | BG27: 确权资料+立项批复 | BH27: 县人力资源和社会保障局
A28: 21 | B28: 林芝市 | C28: 察隅县 | D28: 2019 | E28: 察隅县易地扶贫集中安置点温室配套建设项目 | F28: 是 | G28: 是 | H28: =I28+AF28 -> 1434600 | I28: =O28+J28+T28+Y28+AE28+AC28+AD28 -> 1434600 | J28: =N28+M28+L28+K28 -> 0 | O28: =S28+R28+Q28+P28 -> 1434600 | P28: 940900 | Q28: 493700 | T28: =U28+V28+W28+X28 -> 0 | Y28: =AA28+Z28+AB28 -> 0 | AG28: =AH28+BE28 -> 1212126.3 | AH28: =AN28+AI28+AS28+AX28+BD28+BB28+BC28 -> 1212126.3 | AI28: =AM28+AL28+AK28+AJ28 -> 0 | AN28: =AR28+AQ28+AP28+AO28 -> 1212126.3 | AO28: 940900 | AP28: 271226.34 | AS28: =AW28+AV28+AU28+AT28 -> 0 | AX28: =AZ28+AY28+BA28 -> 0 | BE28: 0 | BF28: 是 | BG28: 确权资料
A29: 22 | B29: 林芝市 | C29: 察隅县 | D29: 2019 | E29: 察隅县竹瓦根镇扎拉村土地平整建设项目 | F29: 是 | G29: 否 | H29: =I29+AF29 -> 2800000 | I29: =O29+J29+T29+Y29+AE29+AC29+AD29 -> 2800000 | J29: =N29+M29+L29+K29 -> 0 | O29: =S29+R29+Q29+P29 -> 2800000 | P29: 819108.28 | S29: 1980891.7 | T29: =U29+V29+W29+X29 -> 0 | Y29: =AA29+Z29+AB29 -> 0 | AG29: =AH29+BE29 -> 2621588.9 | AH29: =AN29+AI29+AS29+AX29+BD29+BB29+BC29 -> 2621588.9 | AI29: =AM29+AL29+AK29+AJ29 -> 0 | AN29: =AR29+AQ29+AP29+AO29 -> 2621588.9 | AO29: 819108.28 | AR29: 1802480.6 | AS29: =AW29+AV29+AU29+AT29 -> 0 | AX29: =AZ29+AY29+BA29 -> 0 | BF29: 是 | BG29: 确权资料+50-1000万台账 | BH29: 竹瓦根镇人民政府
A30: 23 | B30: 林芝市 | C30: 察隅县 | D30: 2019 | E30: 察隅县上察隅镇仕中桥梁新建工程 | F30: 是 | G30: 否 | H30: =I30+AF30 -> 29434900 | I30: =O30+J30+T30+Y30+AE30+AC30+AD30 -> 29434900 | J30: =N30+M30+L30+K30 -> 0 | O30: =S30+R30+Q30+P30 -> 29434900 | P30: 497291.72 | Q30: 18234900 | S30: 10702708 | T30: =U30+V30+W30+X30 -> 0 | Y30: =AA30+Z30+AB30 -> 0 | AG30: =AH30+BE30 -> 29434900 | AH30: =AN30+AI30+AS30+AX30+BD30+BB30+BC30 -> 29434900 | AI30: =AM30+AL30+AK30+AJ30 -> 0 | AN30: =AR30+AQ30+AP30+AO30 -> 29434900 | AO30: 497291.72 | AP30: 18234900 | AR30: 10702708 | AS30: =AW30+AV30+AU30+AT30 -> 0 | AX30: =AZ30+AY30+BA30 -> 0 | BF30: 是 | BG30: 确权资料（确权金额和台账审定金额一致，但是没有支付财评） | BH30: 县交通运输局
A31: 24 | B31: 林芝市 | C31: 察隅县 | D31: 2019 | E31: 察隅县下察隅镇嘎腰村生产道路及桥梁建设项目 | F31: 是 | G31: 否 | H31: =I31+AF31 -> 800000 | I31: =O31+J31+T31+Y31+AE31+AC31+AD31 -> 800000 | J31: =N31+M31+L31+K31 -> 0 | O31: =S31+R31+Q31+P31 -> 800000 | P31: 200000 | Q31: 600000 | T31: =U31+V31+W31+X31 -> 0 | Y31: =AA31+Z31+AB31 -> 0 | AG31: =AH31+BE31 -> 800000 | AH31: =AN31+AI31+AS31+AX31+BD31+BB31+BC31 -> 800000 | AI31: =AM31+AL31+AK31+AJ31 -> 0 | AN31: =AR31+AQ31+AP31+AO31 -> 800000 | AO31: 200000 | AP31: 600000 | AS31: =AW31+AV31+AU31+AT31 -> 0 | AX31: =AZ31+AY31+BA31 -> 0 | BF31: 是 | BG31: 确权资料（确权金额和台账审定金额一致，但是没有支付财评） | BH31: 下察隅人民政府
A32: 25 | B32: 林芝市 | C32: 察隅县 | D32: 2019 | E32: 察隅县上察隅镇竹巴村温室大棚建设项目 | F32: 是 | G32: 是 | H32: =I32+AF32 -> 352000 | I32: =O32+J32+T32+Y32+AE32+AC32+AD32 -> 352000 | J32: =N32+M32+L32+K32 -> 0 | O32: =S32+R32+Q32+P32 -> 352000 | S32: 352000 | T32: =U32+V32+W32+X32 -> 0 | Y32: =AA32+Z32+AB32 -> 0 | AG32: =AH32+BE32 -> 352000 | AH32: =AN32+AI32+AS32+AX32+BD32+BB32+BC32 -> 352000 | AI32: =AM32+AL32+AK32+AJ32 -> 0 | AN32: =AR32+AQ32+AP32+AO32 -> 352000 | AR32: 352000 | AS32: =AW32+AV32+AU32+AT32 -> 0 | AX32: =AZ32+AY32+BA32 -> 0 | BE32: 0 | BF32: 是 | BG32: 确权资料，确权金额和台账审定金额一致，但是没有支付财评 | BH32: 上察隅镇人民政府
A33: 26 | B33: 林芝市 | C33: 察隅县 | D33: 2019 | E33: 察隅县竹瓦根镇嘎达村新建蓄水池项目 | F33: 是 | G33: 否 | H33: =I33+AF33 -> 216000 | I33: =O33+J33+T33+Y33+AE33+AC33+AD33 -> 216000 | J33: =N33+M33+L33+K33 -> 0 | O33: =S33+R33+Q33+P33 -> 216000 | P33: 216000 | T33: =U33+V33+W33+X33 -> 0 | Y33: =AA33+Z33+AB33 -> 0 | AG33: =AH33+BE33 -> 216000 | AH33: =AN33+AI33+AS33+AX33+BD33+BB33+BC33 -> 216000 | AI33: =AM33+AL33+AK33+AJ33 -> 0 | AN33: =AR33+AQ33+AP33+AO33 -> 216000 | AO33: 216000 | AS33: =AW33+AV33+AU33+AT33 -> 0 | AX33: =AZ33+AY33+BA33 -> 0 | BF33: 是 | BG33: 确权资料 | BH33: 竹瓦根镇人民政府
A34: 27 | B34: 林芝市 | C34: 察隅县 | D34: 2019 | E34: 察隅县竹瓦根镇知美村、曲瓦村新建温室大棚项目 | F34: 是 | G34: 是 | H34: =I34+AF34 -> 584000 | I34: =O34+J34+T34+Y34+AE34+AC34+AD34 -> 584000 | J34: =N34+M34+L34+K34 -> 0 | O34: =S34+R34+Q34+P34 -> 584000 | P34: 6080 | S34: 577920 | T34: =U34+V34+W34+X34 -> 0 | Y34: =AA34+Z34+AB34 -> 0 | AG34: =AH34+BE34 -> 584000 | AH34: =AN34+AI34+AS34+AX34+BD34+BB34+BC34 -> 584000 | AI34: =AM34+AL34+AK34+AJ34 -> 0 | AN34: =AR34+AQ34+AP34+AO34 -> 584000 | AO34: 6080 | AR34: 577920 | AS34: =AW34+AV34+AU34+AT34 -> 0 | AX34: =AZ34+AY34+BA34 -> 0 | BE34: 0 | BF34: 是 | BG34: 确权资料+项目资料 | BH34: 竹瓦根镇人民政府
A35: 28 | B35: 林芝市 | C35: 察隅县 | D35: 2019 | E35: 察隅县竹瓦根镇龙古村灌溉水渠改建工程 | F35: 是 | G35: 否 | H35: =I35+AF35 -> 1574100 | I35: =O35+J35+T35+Y35+AE35+AC35+AD35 -> 1574100 | J35: =N35+M35+L35+K35 -> 0 | O35: =S35+R35+Q35+P35 -> 1574100 | P35: 289500 | S35: 1284600 | T35: =U35+V35+W35+X35 -> 0 | Y35: =AA35+Z35+AB35 -> 0 | AG35: =AH35+BE35 -> 1415805.4 | AH35: =AN35+AI35+AS35+AX35+BD35+BB35+BC35 -> 1415805.4 | AI35: =AM35+AL35+AK35+AJ35 -> 0 | AN35: =AR35+AQ35+AP35+AO35 -> 1415805.4 | AO35: 289500 | AR35: 1126305.4 | AS35: =AW35+AV35+AU35+AT35 -> 0 | AX35: =AZ35+AY35+BA35 -> 0 | BF35: 是 | BG35: 确权资料+50-1000万台账
A36: 29 | B36: 林芝市 | C36: 察隅县 | D36: 2019 | E36: 察隅县下察隅镇共同村昂美组公路改建工程 | F36: 是 | G36: 否 | H36: =I36+AF36 -> 22890900 | I36: =O36+J36+T36+Y36+AE36+AC36+AD36 -> 22890900 | J36: =N36+M36+L36+K36 -> 0 | O36: =S36+R36+Q36+P36 -> 22890900 | S36: 22890900 | T36: =U36+V36+W36+X36 -> 0 | Y36: =AA36+Z36+AB36 -> 0 | AG36: =AH36+BE36 -> 22890900 | AH36: =AN36+AI36+AS36+AX36+BD36+BB36+BC36 -> 22890900 | AI36: =AM36+AL36+AK36+AJ36 -> 0 | AN36: =AR36+AQ36+AP36+AO36 -> 22890900 | AR36: 22890900 | AS36: =AW36+AV36+AU36+AT36 -> 0 | AX36: =AZ36+AY36+BA36 -> 0 | BF36: 是 | BG36: 确权资料+立项批复，审定金额来源不明，已经按22890900元确权
A37: 30 | B37: 林芝市 | C37: 察隅县 | D37: 2019 | E37: 察隅县下察隅镇自更村水渠建设工程 | F37: 是 | G37: 否 | H37: =I37+AF37 -> 945400 | I37: =O37+J37+T37+Y37+AE37+AC37+AD37 -> 945400 | J37: =N37+M37+L37+K37 -> 0 | O37: =S37+R37+Q37+P37 -> 945400 | P37: 945400 | T37: =U37+V37+W37+X37 -> 0 | Y37: =AA37+Z37+AB37 -> 0 | AG37: =AH37+BE37 -> 944500 | AH37: =AN37+AI37+AS37+AX37+BD37+BB37+BC37 -> 944500 | AI37: =AM37+AL37+AK37+AJ37 -> 0 | AN37: =AR37+AQ37+AP37+AO37 -> 944500 | AO37: 146620 | AP37: 797880 | AS37: =AW37+AV37+AU37+AT37 -> 0 | AX37: =AZ37+AY37+BA37 -> 0 | BF37: 是 | BG37: 确权资料+立项批复+50-1000万台账，审定金额来源不明，已经按945400元确权
A38: 31 | B38: 林芝市 | C38: 察隅县 | D38: 2019 | E38: 察隅县竹瓦根镇学尼村现代设施农业建设项目 | F38: 是 | G38: 是 | H38: =I38+AF38 -> 7500000 | I38: =O38+J38+T38+Y38+AE38+AC38+AD38 -> 7500000 | J38: =N38+M38+L38+K38 -> 0 | O38: =S38+R38+Q38+P38 -> 7500000 | P38: 7500000 | T38: =U38+V38+W38+X38 -> 0 | Y38: =AA38+Z38+AB38 -> 0 | AG38: =AH38+BE38 -> 7420825 | AH38: =AN38+AI38+AS38+AX38+BD38+BB38+BC38 -> 7420825 | AI38: =AM38+AL38+AK38+AJ38 -> 0 | AN38: =AR38+AQ38+AP38+AO38 -> 7420825 | AO38: 7420825 | AS38: =AW38+AV38+AU38+AT38 -> 0 | AX38: =AZ38+AY38+BA38 -> 0 | BE38: 0 | BF38: 是 | BG38: 确权资料+50-1000万台账
A39: 32 | B39: 林芝市 | C39: 察隅县 | D39: 2019 | E39: 林芝市察隅县2019年农村饮水安全巩固提升工程 | F39: 是 | G39: 否 | H39: =I39+AF39 -> 6954800 | I39: =O39+J39+T39+Y39+AE39+AC39+AD39 -> 6954800 | J39: =N39+M39+L39+K39 -> 0 | O39: =S39+R39+Q39+P39 -> 6954800 | P39: 2780000 | Q39: 4174800 | T39: =U39+V39+W39+X39 -> 0 | Y39: =AA39+Z39+AB39 -> 0 | AG39: =AH39+BE39 -> 6221460 | AH39: =AN39+AI39+AS39+AX39+BD39+BB39+BC39 -> 6221460 | AI39: =AM39+AL39+AK39+AJ39 -> 0 | AN39: =AR39+AQ39+AP39+AO39 -> 6221460 | AO39: 2780000 | AP39: 3441460 | AS39: =AW39+AV39+AU39+AT39 -> 0 | AX39: =AZ39+AY39+BA39 -> 0 | BF39: 是 | BG39: 确权资料+50-1000万台账 | BH39: 察隅县水利局
A40: 33 | B40: 林芝市 | C40: 察隅县 | D40: 2019 | E40: 察隅县古拉乡则巴村俄库组道路整治工程建 | F40: 是 | G40: 否 | H40: =I40+AF40 -> 965400 | I40: =O40+J40+T40+Y40+AE40+AC40+AD40 -> 965400 | J40: =N40+M40+L40+K40 -> 0 | O40: =S40+R40+Q40+P40 -> 965400 | P40: 965400 | T40: =U40+V40+W40+X40 -> 0 | Y40: =AA40+Z40+AB40 -> 0 | AG40: =AH40+BE40 -> 945500 | AH40: =AN40+AI40+AS40+AX40+BD40+BB40+BC40 -> 945500 | AI40: =AM40+AL40+AK40+AJ40 -> 0 | AN40: =AR40+AQ40+AP40+AO40 -> 945500 | AO40: 945500 | AS40: =AW40+AV40+AU40+AT40 -> 0 | AX40: =AZ40+AY40+BA40 -> 0 | BF40: 是 | BG40: 确权资料+50-1000万台账（审定金额无）+本项目按照945500确权 | BH40: 古拉乡人民政府
...

Sheet 附件3
A1: 西藏自治区察隅县帮扶产业项目总台账 （截至2026年6月30日数据）
A2: 项目 编号 | B2: 项目 地市 | C2: 项目 县区 | D2: 项目 年度 | E2: 项目 名称 | F2: 项目申报主体 | G2: 项目实施地点 | H2: 项目主要建设内容 | I2: 计划投资（万元） | L2: 实际投资（万元） | O2: 项目 分类情况 | P2: 项目所属产业分类 | Q2: 产业“四个一批”分类 | R2: 经营性项目“四个一批”分类 | S2: 项目运营情况 | T2: 项目运营模式 | U2: 项目经营主体 | W2: 项目联农带农协议签订情况 | X2: 项目联农带农协议签订时间 | Y2: 项目联农带农协议主要内容 | Z2: 项目累计分红金额 （元） | AA2: 项目累计带动就业人数 （人） | AB2: 项目归口行业单位名称 | AC2: 备注 | AD2: 是否已经确权 | AE2: 资料来源 | AF2: 本次是否有拍摄现场照片 | AG2: 工作记录是否已写 | AH2: 方案是否已写
I3: 合计 | J3: 政策性资金 （同表2政策性资金合计数） | K3: 其他渠道资金 （如企业自筹、信贷资金等非政策性资金，同表2） | L3: 合计 | M3: 政策性资金 （同表2政策性资金合计数） | N3: 其他渠道资金 （如企业自筹、信贷资金等非政策性资金，同表2） | U3: 经营主体类别 | V3: 名称
A4: 填表说明：根据指南编码规则编号 | D4: 以项目批复中对应内容为准 | G4: 以项目批复中项目实施地点为准，例：XX乡（镇）XX 村（居） | H4: 以项目竣工决算中项目主要建设内容为准 | I4: 与表2数据一致 （保留小数点后面2位） | L4: 与表2数据一致 （保留小数点后面2位） | O4: 在“经营类、公益类、到户类“中选择 | P4: 在“青稞、小麦、饲料、牦牛、乳、羊、猪、鸡、蜂、鱼虾、藏药、茶、葡萄、苹果、猕猴桃、设施农业、乡村旅游、商贸流通、核桃、其他”中选择 | Q4: 在“巩固、升级、盘活、调整”中选择 | R4: 在“巩固、升级、盘活、调整”中选择，仅经营类项目填写 | S4: 根据实际情况填写“是/否” | T4: 在“自主运营、合作运营、委托运营“中选择 | U4: 在“农村集体经济组织、农牧民专业合作社、农户、国企、私企、个体工商户、其他”中选择 | W4: 根据实际情况填写“是/否” | X4: 例：2022.09 | Y4: 例：该项目带动建档立卡群众不低于23户79人增收，分红金额不低于500元/人/年 | AB4: 以项目实施内容对应行业单位为准 | AD4: 在“是/否”中选择 | AE4: 财评、合同、立项等 | AF4: 在“是/否”中选择 | AH4: 在“是/否”中选择
A5: 540425201320001 | B5: 林芝市 | C5: 察隅县 | D5: 2013 | E5: 察瓦龙乡昌西村石榴品种改良项目 | F5: 察瓦龙乡人民政府 | G5: 察瓦龙乡昌西村 | H5: 改良112亩5600株石榴 | I5: =J5+K5 -> 24 | J5: 24 | K5: 0 | L5: =M5+N5 -> 24 | M5: 24 | N5: 0 | O5: 经营类 | P5: 石榴 | Q5: 调整 | R5: 调整 | S5: 否 | AD5: 否 | AE5: 项目资料 | AF5: 否 | AG5: 是 | AH5: 是
A6: 540425201517002 | B6: 林芝市 | C6: 察隅县 | D6: 2015 | E6: 罗马桃花村旅游资源升级改造项目 | F6: 古玉乡人民政府\察隅县受援办 | G6: 古玉乡罗马村 | H6: 发展特色藏民族文化旅游产业，充分发挥旅游、生态自然资源的优势，带动整合闲置劳动力，逐步改变传统农牧业生产方式，进而转变成以旅游业为主的核心产业，建立村民增收的长效机制，促进产业发展，建设幸福新村。内容：1.藏家歌舞表演广场；2.驿站引水工程；3.村内道路硬化工程；4.观景平台；5.绿化种植；6.公共卫生设施等 | I6: =J6+K6 -> 500 | J6: 500 | K6: 0 | L6: =M6+N6 -> 500 | M6: 500 | N6: 0 | O6: 公益类 | P6: 乡村旅游 | Q6: 升级 | AD6: 否 | AE6: 数据统计来源于察隅县2015年援藏投资项目计划表（被审计单位文件夹，附件2：援藏项目）+项目资料 | AF6: 否 | AG6: 是
A7: 540425201517003 | B7: 林芝市 | C7: 察隅县 | D7: 2015 | E7: 察隅县古玉乡罗马村农家乐（实施过，找不到业主） | F7: 罗马村村委会 | G7: 古玉乡罗马村 | H7: 修建农家乐及庭院一座 | I7: =J7+K7 -> 200 | J7: 200 | K7: 0 | L7: =M7+N7 -> 200 | M7: 200 | N7: 0 | O7: 经营类 | P7: 乡村旅游 | Q7: 升级 | R7: 调整 | S7: 否 | T7: 委托运营 | U7: 个体工商户 | V7: 张鹏 | W7: 否 | AB7: 察隅县文化和旅游局 | AD7: 否 | AE7: 数据来源于3.现场踏勘照片-现场及一些现场拍的资料-察隅县-察隅县古玉乡帮扶产业项目统计表 | AF7: 否 | AG7: 是
A8: 540425201619002 | B8: 林芝市 | C8: 察隅县 | D8: 2016 | E8: 古拉乡核桃粮油加工坊 | F8: 察隅县扶贫开发办公室 | G8: 古拉乡 | H8: 购买榨油机及附属配套设施 | I8: =J8+K8 -> 150 | J8: 150 | K8: 0 | L8: =M8+N8 -> 60 | M8: 60 | N8: 0 | O8: 经营类 | P8: 设施农业 | Q8: 升级 | R8: 调整 | S8: 否 | AD8: 否 | AE8: 数据来源于附件8：2016年项目建设计划 | AF8: 否 | AG8: 是
A9: 540425201604002 | B9: 林芝市 | C9: 察隅县 | D9: 2016 | E9: 察隅县牦牛养殖项目 | F9: 扶贫办 | G9: 察隅县 | H9: 为131户购买牛，修建牛圈11座。（古拉乡为8户购置57头牦牛；下察隅镇19户102头修建牛圈11座；竹瓦根镇52户260头；察瓦龙乡52户养殖犏牛410头，奶牛3头，小牛136头，黄牛40头，母牛1头，牛圈1座） | I9: =J9+K9 -> 577 | J9: 577 | K9: 0 | L9: =M9+N9 -> 577 | M9: 577 | N9: 0 | O9: 到户类 | P9: 牦牛 | Q9: 盘活 | AD9: 否 | AE9: 数据来源于附件8：2016年项目建设计划 | AF9: 否 | AG9: 是
A10: 540425201606001 | B10: 林芝市 | C10: 察隅县 | D10: 2016 | E10: 察隅县养羊项目 | F10: 扶贫办 | G10: 察隅县 | H10: 为10户购置山羊550只，绵羊40只（古拉乡3户养殖山羊150只，上察隅镇2户养殖绵羊40只，察瓦龙乡5户养殖山羊400只） | I10: =J10+K10 -> 30 | J10: 30 | K10: 0 | L10: =M10+N10 -> 30 | M10: 30 | N10: 0 | O10: 到户类 | P10: 羊 | Q10: 盘活 | AD10: 否 | AE10: 数据来源于附件8：2016年项目建设计划 | AF10: 否 | AG10: 是
A11: 540425201619003 | B11: 林芝市 | C11: 察隅县 | D11: 2016 | E11: 察隅县特色种植项目 | F11: 扶贫办 | G11: 古拉乡 关龙村 竹瓦根镇 下察隅 | H11: 为9户实施特色种植项目。古拉乡6户（则巴村1户种植葡萄苗30棵，关龙村4户种植花椒苗子80棵，安巴村1户苹果苗50棵）；竹瓦根镇1户（种植天麻）；下察隅镇1户种植橘子树4亩，1户种植天麻2亩。 | I11: =J11+K11 -> 27 | J11: 27 | K11: 0 | L11: =M11+N11 -> 27 | M11: 27 | N11: 0 | O11: 到户类 | P11: 其他 | Q11: 调整 | AD11: 否 | AE11: 数据来源于附件8：2016年项目建设计划 | AF11: 是 | AG11: 是
A12: 540425201619005 | B12: 林芝市 | C12: 察隅县 | D12: 2016 | E12: 古拉乡则巴村菩提树种植及加工项目 | F12: 察隅县扶贫开发办公室 | G12: 古拉乡则巴村 | H12: 种植500颗菩提树 、修建4个树苗培育室3、种植区域土地平整 | I12: =J12+K12 -> 85 | J12: 85 | K12: 0 | L12: =M12+N12 -> 85 | M12: 85 | N12: 0 | O12: 经营类 | P12: 其他 | Q12: 调整 | R12: 调整 | S12: 否 | AC12: 已搬迁 | AD12: 否 | AE12: 数据来源于附件8：2016年项目建设计划 | AF12: 否 | AG12: 是 | AH12: 是
A13: 540425201619006 | B13: 林芝市 | C13: 察隅县 | D13: 2016 | E13: 下察隅镇辣椒种植项目 | F13: 察隅县扶贫开发办公室 | G13: 下察隅镇 | H13: 种植辣椒100亩及附属配套设施 | I13: =J13+K13 -> 60 | J13: 60 | K13: 0 | L13: =M13+N13 -> 60 | M13: 60 | N13: 0 | O13: 经营类 | P13: 其他 | Q13: 调整 | R13: 调整 | S13: 否 | AD13: 否 | AE13: 数据来源于附件8：2016年项目建设计划 | AF13: 否 | AG13: 是
A14: 540425201619007 | B14: 林芝市 | C14: 察隅县 | D14: 2016 | E14: 上察隅镇木碗加工项目 | F14: 扶贫办 | G14: 上察隅镇 | H14: 为上察隅镇木碗加工合作社配置加工设施 | I14: =J14+K14 -> 20 | J14: 20 | K14: 0 | L14: =M14+N14 -> 20 | M14: 20 | N14: 0 | O14: 公益类 | P14: 其他 | Q14: 调整 | AD14: 否 | AE14: 数据来源于附件8：2016年项目建设计划 | AF14: 否 | AG14: 是
A15: 540425201608002 | B15: 林芝市 | C15: 察隅县 | D15: 2016 | E15: 察瓦龙乡藏鸡养殖项目 | F15: 察瓦龙乡人民政府 | G15: 察瓦龙乡 | H15: 建设内容：修建9个鸡圈，购买鸡苗75只，购买饲料等 | I15: =J15+K15 -> 34 | J15: 30 | K15: 4 | L15: =M15+N15 -> 34 | M15: 30 | N15: 4 | O15: 到户类 | P15: 鸡 | Q15: 调整 | S15: 否 | AD15: 是 | AE15: 确权资料+2013年批复项目汇总表 | AG15: 无需写
A16: 540425201607004 | B16: 林芝市 | C16: 察隅县 | D16: 2016 | E16: 察瓦龙乡藏猪养殖项目 | F16: 察瓦龙乡人民政府 | G16: 察瓦龙乡 | H16: 建设内容：修建24个猪圈，化粪池24座，购买猪仔288头，每村购买种猪1头，每户购买可繁育母猪1头，购买饲料等 | I16: =J16+K16 -> 38.907 | J16: 38.907 | K16: 0 | L16: =M16+N16 -> 38.907 | M16: 38.907 | N16: 0 | O16: 到户类 | P16: 猪 | Q16: 调整 | AD16: 否 | AE16: 数据来源于3.现场踏勘照片-现场及一些现场拍的资料-察隅县-察瓦龙乡项目表（最新） | AF16: 否
A17: 540425201616005 | B17: 林芝市 | C17: 察隅县 | D17: 2016 | E17: 察瓦龙乡贫困户温室大棚建设项目 | F17: 察瓦龙乡人民政府 | G17: 察瓦龙乡邓许村、龙普村、昌西村 | H17: 察瓦龙乡修建温室大棚36座，邓许村11座，龙普村21座，昌西村4座 | I17: =J17+K17 -> 57.19 | J17: 57.19 | K17: 0 | L17: =M17+N17 -> 57.19 | M17: 57.19 | N17: 0 | O17: 公益类 | P17: 设施农业 | Q17: 升级 | AD17: 是 | AE17: 在察隅县大棚里面有张确权表 | AF17: 是 | AG17: 是
A18: 540425201608003 | B18: 林芝市 | C18: 察隅县 | D18: 2016 | E18: 察瓦龙乡贫困养鸡项目 | F18: 察瓦龙乡人民政府 | G18: 察瓦龙乡拉卡村、邓许村、昌西村、珠拉村 | H18: 察瓦龙乡扶持贫困户养鸡9户，其中拉卡5户，邓许1户，昌西1户，珠拉2户 | I18: =J18+K18 -> 12.71 | J18: 12.71 | K18: 0 | L18: =M18+N18 -> 12.71 | M18: 12.71 | N18: 0 | O18: 到户类 | P18: 鸡 | Q18: 调整 | AD18: 是 | AE18: 在察隅县养鸡里面有张确权表 | AF18: 否 | AG18: 无需写
A19: 540425201607005 | B19: 林芝市 | C19: 察隅县 | D19: 2016 | E19: 察瓦龙乡贫困户养猪项目 | F19: 察瓦龙乡人民政府 | G19: 察瓦龙乡洪东，昌西，邓许，拉卡，瓦布，学巴，扎然 | H19: 察瓦龙乡扶持贫困户养猪24户，其中拉卡6户，邓许1户，洪东6户，昌西4户，瓦布1户，扎然1户，学巴5户 | I19: =J19+K19 -> 42.06 | J19: 42.06 | K19: 0 | L19: =M19+N19 -> 42.06 | M19: 42.06 | N19: 0 | O19: 到户类 | P19: 猪 | Q19: 调整 | AD19: 是 | AE19: 在察隅县养猪里面有张确权表 | AF19: 否 | AG19: 无需写
A20: 540425201607006 | B20: 林芝市 | C20: 察隅县 | D20: 2016 | E20: 察隅县贫困户藏猪养殖项目 | F20: 察隅县农牧局 | G20: 6个乡镇 | H20: 为我县6个乡镇49个行政村291户建档立卡贫困户修建猪舍5238平方米；购置种公猪49头、种母猪291头、仔猪1272余头。 | I20: =J20+K20 -> 490.394 | J20: 474.2525 | K20: 16.1415 | L20: =M20+N20 -> 474.2525 | M20: 474.2525 | O20: 到户类 | P20: 猪 | Q20: 盘活 | AD20: 是 | AE20: 项目资料 | AF20: 否
A21: 540425201608004 | B21: 林芝市 | C21: 察隅县 | D21: 2016 | E21: 察隅县贫困户养殖鸡项目 | F21: 察隅县农牧局 | G21: 6个乡镇 | H21: 为我县6个乡镇235户建档立卡贫困户修建鸡舍4230平方米；购置鸡苗7600只（公母1：9）；购买饲料等 | I21: =J21+K21 -> 218.605 | J21: 208.605 | K21: 10 | L21: =M21+N21 -> 162.96 | M21: =1629600/10000 -> 162.96 | O21: 到户类 | P21: 鸡 | Q21: 盘活 | AD21: 是 | AE21: 项目资料 | AF21: 否 | AG21: 无需写
A22: 540425201619009 | B22: 林芝市 | C22: 察隅县 | D22: 2016 | E22: 察隅县上察隅镇迟巴村产业扶贫 | F22: 察隅县农牧局 | G22: 上察隅镇迟巴村 | H22: 购买农机具7台；购买猪仔145头，为7户群众修建猪舍140㎡，购买母猪12头，公猪5头；狗仔鸡仔370只，修建鸡舍400㎡；种植板栗核桃8亩；种植黑木耳（每户100菌袋）；种植天麻1800㎡；种植油茶、枇杷180亩 | I22: =J22+K22 -> 160.32 | J22: 160.32 | K22: 0 | L22: =M22+N22 -> 160.32 | M22: 160.32 | N22: 0 | O22: 到户类 | P22: 其他 | Q22: 调整 | S22: 否 | AD22: 否 | AE22: 立项批复，审定金额待定 | AF22: 否 | AG22: 是
A23: 540425201719010 | B23: 林芝市 | C23: 察隅县 | D23: 2017 | E23: 察隅县上察隅镇西巴村珞巴民族服饰加工项目 | F23: 上察隅镇人民政府 | G23: 上察隅镇西巴村 | H23: 修建120米玻璃展柜，购买4台缝纫机，10台编织机，购买编织材料，对原有编织房进行维修以及线路改造 | I23: =J23+K23 -> 24.62 | J23: 24.62 | K23: 0 | L23: =M23+N23 -> 24.62 | M23: 24.62 | N23: 0 | O23: 公益类 | P23: 其他 | Q23: 调整 | S23: 是 | AD23: 是 | AE23: 确权资料 | AF23: 否 | AG23: 无需写
A24: 540425201718001 | B24: 林芝市 | C24: 察隅县 | D24: 2017 | E24: 察隅县察瓦龙乡汽修市场建设项目 | F24: 察隅县扶贫开发投资有限公司 | G24: 察瓦龙乡 | H24: 汽车修理厂849㎡，商业楼2493㎡，洗车间109.12㎡，门卫室14.8㎡，公厕37.41㎡以及大门、室外给排水、室外电气、水泥硬质地面、铺装工程、土石方工程、围墙工程、停车位工程、挡土墙工程、照明工程等 | I24: =J24+K24 -> 1383.28 | J24: 1383.28 | K24: 0 | L24: =M24+N24 -> 1308.153 | M24: 1308.153 | N24: 0 | O24: 经营类 | P24: 商贸流通 | Q24: 巩固 | R24: 巩固 | S24: 是 | T24: 自主运营 | U24: 国企 | V24: 察隅县扶贫开发投资有限公司 | W24: 否 | AB24: 察隅县交通运输局 | AD24: 是 | AE24: 确权资料 | AF24: 是 | AG24: 无需写
A25: 540425201715001 | B25: 林芝市 | C25: 察隅县 | D25: 2017 | E25: 察隅县下察隅镇夏尼村猕猴桃产业园区建设项目 | F25: 察隅县农牧局 | G25: 下察隅镇夏尼村 | H25: 新建培训管理中心212.52㎡，基地入口到培训中心之间道路硬化，硬化面积630.00㎡（道路宽3.5m，长度为180m）及其他配套附属设施建设；种植猕猴桃50亩。 | I25: =J25+K25 -> 150 | J25: 150 | K25: 0 | L25: =M25+N25 -> 132.706 | M25: 132.706 | N25: 0 | O25: 经营类 | P25: 猕猴桃 | Q25: 巩固 | R25: 巩固 | S25: 是 | T25: 委托运营 | U25: 私企 | V25: 察隅县兴农猕猴桃有限公司 | W25: 是 | Y25: 项目盈利时，按照合同约定向村集体分红 | Z25: 99766 | AB25: 察隅县农业农村局​ | AD25: 否 | AE25: 立项+50-1000万台账 | AF25: 否 | AG25: 是
A26: 540425201718002 | B26: 林芝市 | C26: 察隅县 | D26: 2017 | E26: 察隅县汽修市场建设项目 | F26: 察隅县住建局 | G26: 竹瓦根镇 | H26: 1#楼工程（小车机修）2328.31平方米、2#楼工程（大车机修）2510.43平方米、门卫室及附属设施等 | I26: =J26+K26 -> 1936.76 | J26: 1936.76 | K26: 0 | L26: =M26+N26 -> 1904.5077 | M26: 1904.5077 | N26: 0 | O26: 经营类 | P26: 商贸流通 | Q26: 巩固 | R26: 巩固 | S26: 是 | T26: 自主运营 | U26: 国企 | V26: 察隅县扶贫开发投资有限公司 | W26: 否 | AB26: 察隅县交通运输局 | AD26: 否 | AE26: 立项批复+19-25年台账（19年） | AF26: 否 | AG26: 是
A27: 540425201715002 | B27: 林芝市 | C27: 察隅县 | D27: 2017 | E27: 察隅县下察隅镇布巴村等三个行政村猕猴桃种植建设项目 | F27: 下察隅镇人民政府 | G27: 下察隅镇布巴村、京都村、宗古村 | H27: 1、核定布巴村种植猕猴桃370亩，大门一座（含值班室），土地整治及改良370亩，购买种苗37000株，撒播有机肥740吨，修建240立方米（24m×10m×1m）晒水池1处，引水管1300m，修排水沟3374m（0.4m×0.4m），修筑1200m防风林，搭架立桩27750根，牵拉铁丝，安装微喷设备等内容； 2、核定京都村种植猕猴桃243亩，大门一座（含值班室），土地整治及改良243亩，购买种苗24300株，撒播有机肥243吨，网围栏6386米，修建100立方米（10m×10m×1m）晒水池2处，水管道（含1个蓄水池）1024m，搭架立桩18225根，牵拉铁丝，安装微喷设备等内容； 3、核定宗古村种植猕猴桃230亩，大门一座（含值班室），土地整治及改良230亩，购买种苗23000株，撒播有机肥230吨，修筑800米防风林，网围栏3399米，修建100立方米（10m×10m×1m）晒水池2处，引水管道（含1个蓄水池）5800m，搭架立桩17250根，牵拉铁丝，安装微喷设备，修砂石路长1000m（宽3.5m）等内容。 | I27: =J27+K27 -> 2130.42 | J27: 1484.39 | K27: 646.03 | L27: =M27+N27 -> 2100.94 | M27: 1484.39 | N27: 616.55 | O27: 经营类 | P27: 猕猴桃 | Q27: 巩固 | R27: 巩固 | S27: 是 | T27: 委托运营 | U27: 私企 | V27: 察隅县宗古农业发展有限责任公司、察隅县兴农猕猴桃有限公司、西藏林芝察隅巴布吉土地种植专业合作社 | W27: 是 | Z27: 1050407 | AB27: 察隅县农业农村局​ | AC27: 宗古村由察隅县宗古农业发展有限责任公司进行运营、京都村由察隅县兴农猕猴桃有限公司运营、布巴村由西藏林芝察隅巴布吉土地种植专业合作社运营 | AD27: 否 | AE27: 只有电子数据，来源超1000万财评，2019年 | AF27: 是 | AG27: 是
A28: 540425201719011 | B28: 林芝市 | C28: 察隅县 | D28: 2017 | E28: 察隅县古玉乡博学村传统工艺品加工坊项目 | F28: 古玉乡人民政府 | G28: 古玉乡博学村 | H28: 修建传统工艺品加工坊一座 | I28: =J28+K28 -> 36 | J28: 36 | K28: 0 | L28: =M28+N28 -> 36 | M28: 36 | N28: 0 | O28: 经营类 | P28: 商贸流通 | Q28: 巩固 | R28: 调整 | S28: 否 | W28: 否 | AB28: 察隅县农业农村局​ | AD28: 否 | AE28: 数据来源于察隅县古玉乡帮扶产业项目统计表 | AF28: 否 | AG28: 是 | AH28: 是
A29: 540425201719012 | B29: 林芝市 | C29: 察隅县 | D29: 2017 | E29: 察隅县古玉乡罗马村松茸加工坊 | F29: 古玉乡人民政府 | G29: 古玉乡罗马村 | H29: 修建业务用房一座 | I29: =J29+K29 -> 20 | J29: 20 | K29: 0 | L29: =M29+N29 -> 20 | M29: 20 | N29: 0 | O29: 经营类 | P29: 设施农业 | Q29: 升级 | R29: 调整 | S29: 否 | T29: 委托运营 | U29: 个体工商户 | V29: 白玛曲培 | W29: 否 | AB29: 察隅县农业农村局​ | AD29: 否 | AE29: 数据来源于察隅县古玉乡帮扶产业项目统计表 | AF29: 否 | AG29: 是 | AH29: 是
A30: 540425201811001 | B30: 林芝市 | C30: 察隅县 | D30: 2018 | E30: 察隅县察瓦龙乡龙布村重楼种植项目 | F30: 察瓦龙乡人民政府 | G30: 察瓦龙乡龙布村 | H30: “能人+贫困户”，栽种280000株，遮阳网、遮阳架28亩，灌溉水管及土地平整28亩；种苗及设备购置:购买种苗280000株，肥料28吨，病虫害防治及追肥28亩。 | I30: =J30+K30 -> 64.4 | J30: 50 | K30: 14.4 | L30: =M30+N30 -> 64.4 | M30: 50 | N30: 14.4 | O30: 经营类 | P30: 藏药 | Q30: 升级 | R30: 调整 | S30: 否 | AD30: 是 | AE30: 确权资料 | AF30: 否 | AG30: 无需写 | AH30: 是
A31: 540425201811002 | B31: 林芝市 | C31: 察隅县 | D31: 2018 | E31: 察隅县察瓦龙乡扎恩村重楼种植项目 | F31: 察瓦龙乡人民政府 | G31: 察瓦龙乡扎恩村 | H31: “能人+贫困户”，栽种280000株，遮阳网、遮阳架28亩，灌溉水管及土地平整28亩；种苗及设备购置:购买种苗280000株，肥料28吨，病虫害防治及追肥28亩。 | I31: =J31+K31 -> 64.4 | J31: 50 | K31: 14.4 | L31: =M31+N31 -> 64.4 | M31: 50 | N31: 14.4 | O31: 经营类 | P31: 藏药 | Q31: 升级 | R31: 调整 | S31: 否 | AD31: 是 | AE31: 确权资料 | AF31: 否 | AG31: 无需写 | AH31: 是
A32: 540425201816008 | B32: 林芝市 | C32: 察隅县 | D32: 2018 | E32: 察隅县察瓦龙乡苗圃基地建设项目 | F32: 察瓦龙乡人民政府 | G32: 察瓦龙乡 | H32: 项目模式为“能人+贫困户”，PE25灌溉水管及配套设施3000米，土地平整40亩，遮阳网、遮阳架40亩;种苗及设备购置:购买种苗3200株。 | I32: =J32+K32 -> 51.6 | J32: 50 | K32: 1.6 | L32: =M32+N32 -> 51.6 | M32: 50 | N32: 1.6 | O32: 经营类 | P32: 设施农业 | Q32: 升级 | R32: 调整 | S32: 否 | AD32: 是 | AE32: 确权资料 | AF32: 是 | AG32: 无需写 | AH32: 是
A33: 540425201819013 | B33: 林芝市 | C33: 察隅县 | D33: 2018 | E33: 察隅县上察隅镇西巴村铁皮石斛种植扩建项目 | F33: 上察隅镇人民政府 | G33: 上察隅镇西巴村 | H33: 项目模式为“村集体+贫困户”，种植仿野生苗木10亩（含采购苗木60000丛），修建蓄水池1座（长*宽*高为4m*4m*2m），铁丝网围栏1000米，沉砂池、引水渠等。 | I33: =J33+K33 -> 50 | J33: 50 | K33: 0 | L33: =M33+N33 -> 50 | M33: 50 | N33: 0 | O33: 经营类 | P33: 藏药 | Q33: 升级 | R33: 调整 | S33: 是 | T33: 委托运营 | U33: 私企 | V33: 西藏兵哥建筑工程有限公司 | W33: 是 | AD33: 是 | AE33: 确权资料+立项批复 | AF33: 否 | AG33: 无需写 | AH33: 是
A34: 540425201807007 | B34: 林芝市 | C34: 察隅县 | D34: 2018 | E34: 察隅县古玉乡古井村藏香猪养殖项目 | F34: 古玉乡人民政府 | G34: 古玉乡古井村 | H34: 项目模式为“合作社+贫困户”，扩建猪舍53.2㎡；新建铁丝网围栏1300m，办公室及厨房34.44㎡，饲料加工室17.6㎡，育猪室68.04㎡，库房14㎡，待宰室13.44㎡，水池6m3，场地平整765㎡，线路改造、屋面改造1项；采购卫生防疫500头，买种猪340头，购买加工饲料机1台，柴油发电机1台。 | I34: =J34+K34 -> 64.84 | J34: 50 | K34: 14.84 | L34: =M34+N34 -> 64.84 | M34: 50 | N34: 14.84 | O34: 经营类 | P34: 猪 | Q34: 盘活 | R34: 调整 | S34: 是 | T34: 委托运营 | U34: 农牧民专业合作社 | V34: 察隅县古玉乡古井村青冈林藏香猪养殖专业合作社 | W34: 否 | Z34: 28000 | AB34: 察隅县农业农村局​ | AD34: 是 | AE34: 确权资料 | AF34: 是 | AG34: 无需写 | AH34: 是
A35: 540425201808005 | B35: 林芝市 | C35: 察隅县 | D35: 2018 | E35: 察隅县古玉乡古井村藏鸡养殖项目 | F35: 古玉乡人民政府 | G35: 古玉乡古井村 | H35: 项目模式为“能人+贫困户”，新建鸡舍160㎡，新建消毒室、饲料加工间、仓库、职工宿舍64㎡，下蛋室4间，新建蓄水池1座，新建化粪池1座，购置铁丝围栏及立柱550m，场地平整30375m3，道路平整30420m3，铁质大门1座，线路改造1项；种鸡及设备购置费：购买种鸡（藏鸡）1500只，购置饲料加工设备1台，孵化器2台。 | I35: =J35+K35 -> 55.6 | J35: 50 | K35: 5.6 | L35: =M35+N35 -> 55.6 | M35: 50 | N35: 5.6 | O35: 经营类 | P35: 鸡 | Q35: 盘活 | R35: 调整 | S35: 是 | T35: 委托运营 | U35: 个体工商户 | V35: 察隅县兄弟藏鸡养殖场 | W35: 否 | Z35: 51700 | AB35: 察隅县农业农村局​ | AD35: 是 | AE35: 确权资料 | AF35: 是 | AG35: 无需写 | AH35: 是
A36: 540425201807008 | B36: 林芝市 | C36: 察隅县 | D36: 2018 | E36: 察隅县竹瓦根镇扎拉村阿多专业养殖合作社项目 | F36: 竹瓦根镇人民政府 | G36: 竹瓦根镇扎拉村 | H36: 项目模式为“合作社+贫困户”，平整土地2000㎡；新建猪圈20间，总建筑面积340㎡；新建化粪池1座；新建消毒室1座，建筑面积17.6㎡；PE32给水管200m，DN110排污管200m。采购猪苗100头，消毒设备（型号BG-C4）1台 | I36: =J36+K36 -> 71.44 | J36: 50 | K36: 21.44 | L36: =M36+N36 -> 71.44 | M36: 50 | N36: 21.44 | O36: 经营类 | P36: 猪 | Q36: 盘活 | R36: 盘活 | S36: 是 | T36: 委托运营 | U36: 农户 | V36: 刘勇 | AB36: 察隅县农业农村局​ | AD36: 是 | AE36: 确权资料 | AF36: 是 | AG36: 无需写 | AH36: 是
A37: 540425201807009 | B37: 林芝市 | C37: 察隅县 | D37: 2018 | E37: 察隅县竹瓦根镇桑久村藏香猪养殖项目 | F37: 竹瓦根镇人民政府 | G37: 竹瓦根镇桑久村 | H37: 项目模式为“村集体+贫困户”， 新建围墙200m，铁大门1扇，给水管100m，铜芯线100m，仓库及饲养员室1间，消毒室1间，猪圈14间，化粪池1座;设备购置:电力变压器1台，消毒设备1台，种猪1头，母猪10头，猪仔90头 | I37: =J37+K37 -> 53.08 | J37: 50 | K37: 3.08 | L37: =M37+N37 -> 53.08 | M37: 50 | N37: 3.08 | O37: 经营类 | P37: 猪 | Q37: 盘活 | R37: 调整 | S37: 是 | T37: 委托运营 | U37: 农户 | V37: 扎西次仁 | Z37: 41680 | AB37: 察隅县农业农村局​ | AD37: 是 | AE37: 确权资料 | AF37: 是 | AG37: 无需写 | AH37: 是
A38: 540425201805001 | B38: 林芝市 | C38: 察隅县 | D38: 2018 | E38: 察隅县古玉乡博学村犏奶牛养殖场扩建项目 | F38: 古玉乡人民政府 | G38: 古玉乡博学村 | H38: 项目模式为“合作社+贫困户”，新建牛圈319.64m2，建筑工程319.64m2，安装工程319.64m2，大门1座，围墙120m；购置犏奶牛：母牛20头，公牛3头。 | I38: =J38+K38 -> 72.58 | J38: 50 | K38: 22.58 | L38: =M38+N38 -> 72.58 | M38: 50 | N38: 22.58 | O38: 经营类 | P38: 乳 | Q38: 升级 | R38: 升级 | S38: 是 | T38: 委托运营 | U38: 农牧民专业合作社 | V38: 察隅县古玉乡博学村杰荣养殖专业合作社 | W38: 否 | Z38: 76100 | AB38: 察隅县农业农村局​ | AD38: 是 | AE38: 确权资料 | AF38: 否 | AG38: 无需写
A39: 540425201807010 | B39: 林芝市 | C39: 察隅县 | D39: 2018 | E39: 下察隅镇京都村藏香猪养殖项目 | F39: 下察隅镇人民政府 | G39: 下察隅镇京都村 | H39: 1.扩建猪舍面积153.88平方米；2.新建饲料库房及饲料加工房70.56平方米；3.建蓄水池1座（采用砖混结构长3m*宽4m*高1.2m）；4.买可繁育母猪60头（繁育母猪需为已生育过1窝猪仔的母猪）、种猪3头（种猪年龄1.5-2年）；5.购买加工饲料机1台（型号：9FQ40-28,动力：11-15kw）;6.购买柴油发电机1台（型号：L32-R00，功率：11-15KW）；7.新建猪舍C20混凝土硬化路面91.02平方米；8.PE水管直径75mmPE管300m,PE水管直径25mmPE管260m;9.新建简易木桥一座，采用木质结构（10米*2米）；10.原猪舍铁皮100张；11.铁丝围栏700m,围栏1.5m高，每隔3米设置一根圆钢管立柱，立柱高3m,立柱基础埋深30cm；11.新建大门2个（2m*3m）。 | I39: =J39+K39 -> 54.44 | J39: 50 | K39: 4.44 | L39: =M39+N39 -> 54.44 | M39: 50 | N39: 4.44 | O39: 经营类 | P39: 猪 | Q39: 盘活 | R39: 升级 | S39: 是 | T39: 委托运营 | U39: 农牧民专业合作社 | V39: 下察隅镇京都村阿胖养殖专业合作社 | AB39: 察隅县农业农村局​ | AD39: 是 | AE39: 确权资料 | AF39: 是 | AG39: 无需写
A40: 540425201807011 | B40: 林芝市 | C40: 察隅县 | D40: 2018 | E40: 察隅县古拉乡俄玉村藏香猪养殖项目 | F40: 古拉乡人民政府 | G40: 古拉乡俄玉村 | H40: 项目模式为“合作社+贫困户”，建设猪舍105.7㎡，育种室和隔离室164.16㎡，仓库及管理用房68.64㎡，围墙200m，供水1项，购买猪仔80头，种猪4头，能繁母猪20头，饲料、防疫及运转费用1项，供电1项。 | I40: =J40+K40 -> 50 | J40: 50 | K40: 0 | L40: =M40+N40 -> 50 | M40: 50 | N40: 0 | O40: 经营类 | P40: 猪 | Q40: 盘活 | R40: 盘活 | S40: 是 | W40: 否 | AB40: 察隅县农业农村局 | AD40: 是 | AE40: 确权资料 | AF40: 是 | AG40: 无需写 | AH40: 是
...

Sheet 附件5-1
A1: 西藏自治区察隅县帮扶产业项目资产总台账 （截至2026年6月20日数据）
A2: 项目 编号 | B2: 项目县区 | C2: 项目年度 | D2: 项目名称 | E2: 项目实际投入金额 （万元） | F2: 资产 个数 | G2: 资产原值总金额（万元） | H2: 资产净值总金额 （万元） | I2: 资产属性 | J2: 资产“五权”确权主体 | P2: 备注
J3: 所有权 | L3: 经营权主体名称 | M3: 收益权主体名称 | N3: 监督权主体名称 | O3: 处置权主体名称
J4: 主体类别 | K4: 名称
A5: 填表说明：与表3项目编号一致 | D5: 一个项目仅填写一行 | E5: 与表2项目实际投资金额合计数一致 | F5: 应为项目实际形成资产个数合计数 | G5: 应为项目实际形成资产总数 （保留小数点后面2位） | H5: 统计时间为截止2024年12月31日 | I5: 在“国有资产、集体资产、到户资产”中选择 | J5: 在“农村集体经济组织、农户、国企、乡（镇）人民政府”中选择
A6: 540425201916012 | B6: 察隅县 | C6: 2019 | D6: 察隅县竹瓦根镇学尼村现代设施农业建设项目 | E6: 742.0825 | F6: =SUMIF('附件5-2'!$A$4:$A$336,A6,'附件5-2'!$I$4:$I$336) -> 4 | G6: 742 | H6: 519.4 | I6: 集体资产 | J6: 农村集体经济组织 | K6: 林芝市察隅县竹瓦根镇学尼村股份经济合作社 | L6: 察隅县牧丰绿色农业有限公司 | M6: 林芝市察隅县竹瓦根镇学尼村股份经济合作社 | N6: 西藏自治区林芝市察隅县竹瓦根镇学尼村村民委员会 | O6: 林芝市察隅县竹瓦根镇学尼村股份经济合作社
A7: 540425202116013 | B7: 察隅县 | C7: 2021 | D7: 察隅县竹瓦根镇城郊蔬菜种植项目 | E7: 371.55905 | F7: =SUMIF('附件5-2'!$A$4:$A$336,A7,'附件5-2'!$I$4:$I$336) -> 3 | G7: 371.55905 | H7: 315.82519 | I7: 集体资产 | J7: 农村集体经济组织 | K7: 林芝市察隅县竹瓦根镇学尼村股份经济合作社 | L7: 察隅县牧丰绿色农业有限公司 | M7: 林芝市察隅县竹瓦根镇学尼村股份经济合作社 | N7: 西藏自治区林芝市察隅县竹瓦根镇学尼村村民委员会 | O7: 林芝市察隅县竹瓦根镇学尼村股份经济合作社
A8: 540425201908006 | B8: 察隅县 | C8: 2019 | D8: 竹瓦根镇空档村“4+1”藏鸡养殖项目 | E8: 60 | F8: =SUMIF('附件5-2'!$A$4:$A$336,A8,'附件5-2'!$I$4:$I$336) -> 3 | G8: 59.05 | H8: 42.811249 | I8: 集体资产 | J8: 农村集体经济组织 | K8: 林芝市察隅县竹瓦根镇空档村股份经济合作社 | L8: 布索朗 | M8: 林芝市察隅县竹瓦根镇空档村股份经济合作社 | N8: 西藏自治区林芝市察隅县竹瓦根镇空档村村民委员会 | O8: 林芝市察隅县竹瓦根镇空档村股份经济合作社
A9: 540425202019028 | B9: 察隅县 | C9: 2020 | D9: 察隅县雪颠57啤酒厂改扩建项目 | E9: 379 | F9: =SUMIF('附件5-2'!$A$4:$A$336,A9,'附件5-2'!$I$4:$I$336) -> 9 | G9: 379 | H9: 189.5 | I9: 国有资产 | J9: 国企 | K9: 察隅县雪巅啤酒有限公司 | L9: 察隅县雪巅啤酒有限公司 | M9: 察隅县雪巅啤酒有限公司 | N9: 西藏自治区察隅县国有资产经营有限公司 | O9: 察隅县雪巅啤酒有限公司
A10: 540425201807008 | B10: 察隅县 | C10: 2018 | D10: 察隅县竹瓦根镇扎拉村阿多专业养殖合作社项目 | E10: 50 | F10: =SUMIF('附件5-2'!$A$4:$A$336,A10,'附件5-2'!$I$4:$I$336) -> 1 | G10: 50 | H10: 38.333333 | I10: 集体资产 | J10: 农村集体经济组织 | K10: 林芝市察隅县竹瓦根镇扎拉村股份经济合作社 | L10: 刘勇 | M10: 林芝市察隅县竹瓦根镇扎拉村股份经济合作社 | N10: 西藏自治区林芝市察隅县竹瓦根镇扎拉村村民委员会 | O10: 林芝市察隅县竹瓦根镇扎拉村股份经济合作社
A11: 540425201807009 | B11: 察隅县 | C11: 2018 | D11: 察隅县竹瓦根镇桑久村藏香猪养殖项目 | E11: 50 | F11: =SUMIF('附件5-2'!$A$4:$A$336,A11,'附件5-2'!$I$4:$I$336) -> 3 | G11: 52.88 | H11: 31.976 | I11: 集体资产 | J11: 农村集体经济组织 | K11: 林芝市察隅县竹瓦根镇桑久村股份经济合作社 | L11: 扎西次仁 | M11: 林芝市察隅县竹瓦根镇桑久村股份经济合作社 | N11: 西藏自治区林芝市察隅县竹瓦根镇桑久村村民委员会 | O11: 林芝市察隅县竹瓦根镇桑久村股份经济合作社
A12: 540425201918003 | B12: 察隅县 | C12: 2019 | D12: 察隅县竹瓦根镇沙通坝建材市场建设项目 | E12: 2326.1826 | F12: =SUMIF('附件5-2'!$A$4:$A$336,A12,'附件5-2'!$I$4:$I$336) -> 7 | G12: 2326.1826 | H12: 1949.85 | I12: 国有资产 | J12: 国企 | K12: 察隅县扶贫开发投资有限公司 | L12: 察隅县扶贫开发投资有限公司 | M12: 察隅县扶贫开发投资有限公司 | N12: 察隅县国有资产监督管理委员会 | O12: 察隅县扶贫开发投资有限公司
A13: 540425201908007 | B13: 察隅县 | C13: 2019 | D13: 察隅县竹瓦根镇扎拉村“4+1”藏鸡养殖项目 | E13: 30 | F13: =SUMIF('附件5-2'!$A$4:$A$336,A13,'附件5-2'!$I$4:$I$336) -> 296 | G13: 30 | H13: 20.049333 | I13: 集体资产 | J13: 农村集体经济组织 | K13: 林芝市察隅县竹瓦根镇扎拉村股份经济合作社 | L13: 成晓 | M13: 林芝市察隅县竹瓦根镇扎拉村股份经济合作社 | N13: 西藏自治区林芝市察隅县竹瓦根镇扎拉村村民委员会 | O13: 林芝市察隅县竹瓦根镇扎拉村股份经济合作社
A14: 540425202117014 | B14: 察隅县 | C14: 2021 | D14: 察隅县竹瓦根镇学尼村旅游配套设施建设项目 | E14: 242.17359 | F14: =SUMIF('附件5-2'!$A$4:$A$336,A14,'附件5-2'!$I$4:$I$336) -> 1 | G14: 242.17359 | H14: 215.93812 | I14: 集体资产 | J14: 农村集体经济组织 | K14: 林芝市察隅县竹瓦根镇学尼村股份经济合作社 | L14: 彭琼玲 | M14: 林芝市察隅县竹瓦根镇学尼村股份经济合作社 | N14: 西藏自治区林芝市察隅县竹瓦根镇学尼村村民委员会 | O14: 林芝市察隅县竹瓦根镇学尼村股份经济合作社
A15: 540425202104006 | B15: 察隅县 | C15: 2021 | D15: 察隅县竹瓦根镇高寒牧区高产养殖项目二期 | E15: 383.32645 | F15: =SUMIF('附件5-2'!$A$4:$A$336,A15,'附件5-2'!$I$4:$I$336) -> 118 | G15: 383.32645 | H15: 218.15905 | I15: 集体资产 | J15: 农村集体经济组织 | K15: 林芝市察隅县竹瓦根镇嘎达村股份经济合作社 | L15: 西藏察鑫农业科技有限公司 | M15: 林芝市察隅县竹瓦根镇嘎达村股份经济合作社 | N15: 西藏自治区林芝市察隅县竹瓦根镇嘎达村村民委员会 | O15: 林芝市察隅县竹瓦根镇嘎达村股份经济合作社
A16: 540425202004005 | B16: 察隅县 | C16: 2020 | D16: 察隅县竹瓦根镇高寒牧区高产养殖项目 | E16: 247.92948 | F16: =SUMIF('附件5-2'!$A$4:$A$336,A16,'附件5-2'!$I$4:$I$336) -> 94 | G16: 247.92948 | H16: 110.00961 | I16: 集体资产 | J16: 农村集体经济组织 | K16: 察隅县竹瓦根镇日东片区农畜产品专业合作社 | L16: 西藏察鑫农业科技有限公司 | M16: 察隅县竹瓦根镇日东片区农畜产品专业合作社 | N16: 察隅县竹瓦根镇日东片区农畜产品专业合作社 | O16: 察隅县竹瓦根镇日东片区农畜产品专业合作社
A17: 540425201619038 | B17: 察隅县 | C17: 2016 | D17: 察隅县古玉乡然乌学村茶馆 | E17: 30 | F17: =SUMIF('附件5-2'!$A$4:$A$336,A17,'附件5-2'!$I$4:$I$336) -> 1 | G17: 30 | H17: 17.875 | I17: 集体资产 | J17: 农村集体经济组织 | K17: 林芝市察隅县古玉乡然乌学村股份经济合作社 | M17: 林芝市察隅县古玉乡然乌学村股份经济合作社 | N17: 西藏自治区林芝市察隅县古玉乡然乌学村村民委员会 | O17: 林芝市察隅县古玉乡然乌学村股份经济合作社
A18: 540425201719011 | B18: 察隅县 | C18: 2017 | D18: 察隅县古玉乡博学村传统工艺品加工坊项目 | E18: 36 | F18: =SUMIF('附件5-2'!$A$4:$A$336,A18,'附件5-2'!$I$4:$I$336) -> 2 | G18: 36 | H18: 21.958333 | I18: 集体资产 | J18: 农村集体经济组织 | K18: 林芝市察隅县古玉乡博学村股份经济合作社 | M18: 林芝市察隅县古玉乡博学村股份经济合作社 | N18: 西藏自治区林芝市察隅县古玉乡博学村村民委员会 | O18: 林芝市察隅县古玉乡博学村股份经济合作社
A19: 540425201805001 | B19: 察隅县 | C19: 2018 | D19: 察隅县古玉乡博学村犏奶牛养殖场扩建项目 | E19: 50 | F19: =SUMIF('附件5-2'!$A$4:$A$336,A19,'附件5-2'!$I$4:$I$336) -> 1 | G19: 50 | H19: 36.458333 | I19: 集体资产 | J19: 农村集体经济组织 | K19: 林芝市察隅县古玉乡博学村股份经济合作社 | L19: 察隅县古玉乡博学村杰荣养殖专业合作社 | M19: 林芝市察隅县古玉乡博学村股份经济合作社 | N19: 西藏自治区林芝市察隅县古玉乡博学村村民委员会 | O19: 林芝市察隅县古玉乡博学村股份经济合作社
A20: 540425201819018 | B20: 察隅县 | C20: 2018 | D20: 察隅县古玉乡然乌学村然乌学组松茸加工坊 | E20: 40 | F20: =SUMIF('附件5-2'!$A$4:$A$336,A20,'附件5-2'!$I$4:$I$336) -> 3 | G20: 40 | H20: 24.05 | I20: 集体资产 | J20: 农村集体经济组织 | K20: 林芝市察隅县古玉乡然乌学村股份经济合作社 | M20: 林芝市察隅县古玉乡然乌学村股份经济合作社 | N20: 西藏自治区林芝市察隅县古玉乡然乌学村村民委员会 | O20: 林芝市察隅县古玉乡然乌学村股份经济合作社
A21: 540425202204008 | B21: 察隅县 | C21: 2022 | D21: 察隅县古玉乡巴依、玉和村犏牛养殖项目 | E21: 945.20898 | F21: =SUMIF('附件5-2'!$A$4:$A$336,A21,'附件5-2'!$I$4:$I$336) -> 180 | G21: =E21 -> 945.20898 | H21: 801.96832 | I21: 集体资产 | J21: 农村集体经济组织 | K21: 林芝市察隅县古玉乡巴依村股份经济合作社、林芝市察隅县古玉乡玉和村股份经济合作社 | L21: 西藏察鑫农业科技有限公司 | M21: 林芝市察隅县古玉乡巴依村股份经济合作社、林芝市察隅县古玉乡玉和村股份经济合作社 | N21: 西藏自治区林芝市察隅县古玉乡巴依村村民委员会、西藏自治区林芝市察隅县古玉乡巴玉和村村民委员会 | O21: 林芝市察隅县古玉乡巴依村股份经济合作社、林芝市察隅县古玉乡玉和村股份经济合作社
A22: 540425201718002 | B22: 察隅县 | C22: 2017 | D22: 察隅县汽修市场建设项目 | E22: 1904.5077 | F22: =SUMIF('附件5-2'!$A$4:$A$336,A22,'附件5-2'!$I$4:$I$336) -> 3 | G22: 1904.5077 | H22: 1301.4136 | I22: 国有资产 | J22: 国企 | K22: 察隅县扶贫开发投资有限公司 | L22: 察隅县扶贫开发投资有限公司 | M22: 察隅县扶贫开发投资有限公司 | N22: 察隅县国有资产监督管理委员会 | O22: 察隅县扶贫开发投资有限公司
A23: 540425201807007 | B23: 察隅县 | C23: 2018 | D23: 察隅县古玉乡古井村藏香猪养殖项目 | E23: 76.36 | F23: =SUMIF('附件5-2'!$A$4:$A$336,A23,'附件5-2'!$I$4:$I$336) -> 232 | G23: 50 | H23: 19.519793 | I23: 集体资产 | J23: 农村集体经济组织 | K23: 林芝市察隅县古玉乡古井村股份经济合作社 | L23: 察隅县古玉乡古井村青冈林藏香猪养殖专业合作社 | M23: 林芝市察隅县古玉乡古井村股份经济合作社 | N23: 西藏自治区林芝市察隅县古玉乡古井村村民委员会 | O23: 林芝市察隅县古玉乡古井村股份经济合作社
A24: 540425201808005 | B24: 察隅县 | C24: 2018 | D24: 察隅县古玉乡古井村藏鸡养殖项目 | E24: 50 | F24: =SUMIF('附件5-2'!$A$4:$A$336,A24,'附件5-2'!$I$4:$I$336) -> 1137 | G24: 50 | H24: 21.583333 | I24: 集体资产 | J24: 农村集体经济组织 | K24: 林芝市察隅县古玉乡古井村股份经济合作社 | L24: 察隅县兄弟藏鸡养殖场 | M24: 林芝市察隅县古玉乡古井村股份经济合作社 | N24: 西藏自治区林芝市察隅县古玉乡古井村村民委员会 | O24: 林芝市察隅县古玉乡古井村股份经济合作社
A25: 540425201819017 | B25: 察隅县 | C25: 2018 | D25: 察隅县古玉乡古井村松茸加工房 | E25: 30 | F25: =SUMIF('附件5-2'!$A$4:$A$336,A25,'附件5-2'!$I$4:$I$336) -> 1 | G25: 30 | H25: 19.5 | I25: 集体资产 | J25: 农村集体经济组织 | K25: 林芝市察隅县古玉乡古井村股份经济合作社 | L25: 乔君伟 | M25: 林芝市察隅县古玉乡古井村股份经济合作社 | N25: 西藏自治区林芝市察隅县古玉乡古井村村民委员会 | O25: 林芝市察隅县古玉乡古井村股份经济合作社
A26: 540425201517003 | B26: 察隅县 | C26: 2015 | D26: 察隅县古玉乡罗马村农家乐 | E26: 200 | F26: =SUMIF('附件5-2'!$A$4:$A$336,A26,'附件5-2'!$I$4:$I$336) -> 1 | G26: 200 | H26: 109.16667 | I26: 集体资产 | J26: 农村集体经济组织 | K26: 林芝市察隅县古玉乡罗马村股份经济合作社 | L26: 张鹏 | M26: 林芝市察隅县古玉乡罗马村股份经济合作社 | N26: 西藏自治区林芝市察隅县古玉乡罗马村村民委员会 | O26: 林芝市察隅县古玉乡罗马村股份经济合作社
A27: 540425202117015 | B27: 察隅县 | C27: 2021 | D27: 察隅县古玉乡罗马村宾馆 | E27: 400 | F27: =SUMIF('附件5-2'!$A$4:$A$336,A27,'附件5-2'!$I$4:$I$336) -> 1 | G27: 400 | H27: 338.33333 | I27: 集体资产 | J27: 农村集体经济组织 | K27: 林芝市察隅县古玉乡罗马村股份经济合作社 | L27: 王新华 | M27: 林芝市察隅县古玉乡罗马村股份经济合作社 | N27: 西藏自治区林芝市察隅县古玉乡罗马村村民委员会 | O27: 林芝市察隅县古玉乡罗马村股份经济合作社
A28: 540425201304001 | B28: 察隅县 | C28: 2013 | D28: 察隅县古玉乡罗马村犏牛养殖场 | E28: 151 | F28: =SUMIF('附件5-2'!$A$4:$A$336,A28,'附件5-2'!$I$4:$I$336) -> 3 | G28: 151 | H28: 67.320833 | I28: 集体资产 | J28: 农村集体经济组织 | K28: 林芝市察隅县古玉乡罗马村股份经济合作社 | M28: 林芝市察隅县古玉乡罗马村股份经济合作社 | N28: 西藏自治区林芝市察隅县古玉乡罗马村村民委员会 | O28: 林芝市察隅县古玉乡罗马村股份经济合作社
A29: 540425201719012 | B29: 察隅县 | C29: 2017 | D29: 察隅县古玉乡罗马村松茸加工坊 | E29: 20 | F29: =SUMIF('附件5-2'!$A$4:$A$336,A29,'附件5-2'!$I$4:$I$336) -> 1 | G29: 20 | H29: 12.916667 | I29: 集体资产 | J29: 农村集体经济组织 | K29: 林芝市察隅县古玉乡罗马村股份经济合作社 | L29: 白玛曲培 | M29: 林芝市察隅县古玉乡罗马村股份经济合作社 | N29: 西藏自治区林芝市察隅县古玉乡罗马村村民委员会 | O29: 林芝市察隅县古玉乡罗马村股份经济合作社
A30: 540425201807010 | B30: 察隅县 | C30: 2018 | D30: 下察隅镇京都村藏香猪养殖项目 | E30: 50 | F30: =SUMIF('附件5-2'!$A$4:$A$336,A30,'附件5-2'!$I$4:$I$336) -> 67 | G30: 50 | H30: 20.182334 | I30: 集体资产 | J30: 农村集体经济组织 | K30: 林芝市察隅县下察隅镇京都村股份经济合作社 | L30: 下察隅镇京都村阿胖养殖专业合作社 | M30: 林芝市察隅县下察隅镇京都村股份经济合作社 | N30: 西藏自治区林芝市察隅县下察隅镇京都村村民委员会 | O30: 林芝市察隅县下察隅镇京都村股份经济合作社
A31: 540425202019030 | B31: 察隅县 | C31: 2020 | D31: 察隅县下察隅镇京都村柑橘项目 | E31: 59.36 | F31: =SUMIF('附件5-2'!$A$4:$A$336,A31,'附件5-2'!$I$4:$I$336) -> 2 | G31: 60 | H31: 30 | I31: 集体资产 | J31: 农村集体经济组织 | K31: 林芝市察隅县下察隅镇京都村股份经济合作社 | L31: 察隅县兴农猕猴桃有限公司 | M31: 林芝市察隅县下察隅镇京都村股份经济合作社 | N31: 西藏自治区林芝市察隅县下察隅镇京都村村民委员会 | O31: 林芝市察隅县下察隅镇京都村股份经济合作社
A32: 540425201907012 | B32: 察隅县 | C32: 2019 | D32: 下察隅镇沙琼村藏香猪养殖项目 | E32: 50 | F32: =SUMIF('附件5-2'!$A$4:$A$336,A32,'附件5-2'!$I$4:$I$336) -> 69 | G32: 50 | H32: 18.342334 | I32: 集体资产 | J32: 农村集体经济组织 | K32: 林芝市察隅县下察隅镇沙琼村股份经济合作社 | L32: 察隅县下察隅镇沙琼村小次仁农民专业合作社 | M32: 林芝市察隅县下察隅镇沙琼村股份经济合作社 | N32: 西藏自治区林芝市察隅县下察隅镇沙琼村村民委员会 | O32: 林芝市察隅县下察隅镇沙琼村股份经济合作社
A33: 540425202315008 | B33: 察隅县 | C33: 2023 | D33: 察隅县下察隅镇沙琼村、洞冲村入股猕猴桃基地项目 | E33: 140 | F33: =SUMIF('附件5-2'!$A$4:$A$336,A33,'附件5-2'!$I$4:$I$336) -> 1 | G33: 140 | H33: 0 | I33: 集体资产 | J33: 农村集体经济组织 | K33: 林芝市察隅县下察隅镇沙琼村股份经济合作社、林芝市察隅县下察隅镇洞冲村股份经济合作社 | L33: 林芝华源佳隅农业科技开发有限公司 | M33: 林芝市察隅县下察隅镇沙琼村股份经济合作社、林芝市察隅县下察隅镇洞冲村股份经济合作社 | N33: 西藏自治区林芝市察隅县下察隅镇沙琼村村民委员会、西藏自治区林芝市察隅县下察隅镇洞冲村村民委员会 | O33: 林芝市察隅县下察隅镇沙琼村股份经济合作社、林芝市察隅县下察隅镇洞冲村股份经济合作社
A34: 540425202204009 | B34: 察隅县 | C34: 2022 | D34: 察隅县古玉乡犏牛养殖场配套设施项目 | E34: 94.24684 | F34: =SUMIF('附件5-2'!$A$4:$A$336,A34,'附件5-2'!$I$4:$I$336) -> 1 | G34: 94.24684 | H34: 86.785632 | I34: 集体资产 | J34: 农村集体经济组织 | K34: 林芝市察隅县古玉乡罗马村股份经济合作社 | M34: 林芝市察隅县古玉乡罗马村股份经济合作社 | N34: 西藏自治区林芝市察隅县古玉乡罗马村村民委员会 | O34: 林芝市察隅县古玉乡罗马村股份经济合作社
A35: 540425201715001 | B35: 察隅县 | C35: 2017 | D35: 察隅县下察隅镇夏尼村猕猴桃产业园区建设项目 | E35: 132.706 | F35: =SUMIF('附件5-2'!$A$4:$A$336,A35,'附件5-2'!$I$4:$I$336) -> 6003 | G35: 126.006 | H35: 71.056233 | I35: 集体资产 | J35: 农村集体经济组织 | K35: 林芝市察隅县下察隅镇夏尼村股份经济合作社 | L35: 察隅县兴农猕猴桃有限公司 | M35: 林芝市察隅县下察隅镇夏尼村股份经济合作社 | N35: 西藏自治区林芝市察隅县下察隅镇夏尼村村民委员会 | O35: 林芝市察隅县下察隅镇夏尼村股份经济合作社
A36: 540425202115006 | B36: 察隅县 | C36: 2021 | D36: 察隅县下察隅镇夏尼村猕猴桃种植项目 | E36: 229.48 | F36: =SUMIF('附件5-2'!$A$4:$A$336,A36,'附件5-2'!$I$4:$I$336) -> 100 | G36: 229.48 | H36: 160.636 | I36: 集体资产 | J36: 农村集体经济组织 | K36: 林芝市察隅县下察隅镇夏尼村股份经济合作社 | L36: 察隅县兴农猕猴桃有限公司 | M36: 林芝市察隅县下察隅镇夏尼村股份经济合作社 | N36: 西藏自治区林芝市察隅县下察隅镇夏尼村村民委员会 | O36: 林芝市察隅县下察隅镇夏尼村股份经济合作社
A37: 540425202115004 | B37: 察隅县 | C37: 2021 | D37: 察隅县下察隅镇夏尼村猕猴桃园提升项目 | E37: 65.475 | F37: =SUMIF('附件5-2'!$A$4:$A$336,A37,'附件5-2'!$I$4:$I$336) -> 1 | G37: 11.52 | H37: 7.872 | I37: 集体资产 | J37: 农村集体经济组织 | K37: 林芝市察隅县下察隅镇夏尼村股份经济合作社 | M37: 林芝市察隅县下察隅镇夏尼村股份经济合作社 | N37: 西藏自治区林芝市察隅县下察隅镇夏尼村村民委员会 | O37: 林芝市察隅县下察隅镇夏尼村股份经济合作社
A38: 540425202117013 | B38: 察隅县 | C38: 2021 | D38: 察隅县下察隅镇夏尼村旅游配套设施建设项目 | E38: 45 | F38: =SUMIF('附件5-2'!$A$4:$A$336,A38,'附件5-2'!$I$4:$I$336) -> 10 | G38: 45 | H38: 30.749999 | I38: 集体资产 | J38: 农村集体经济组织 | K38: 林芝市察隅县下察隅镇夏尼村股份经济合作社 | M38: 林芝市察隅县下察隅镇夏尼村股份经济合作社 | N38: 西藏自治区林芝市察隅县下察隅镇夏尼村村民委员会 | O38: 林芝市察隅县下察隅镇夏尼村股份经济合作社
A39: 540425202212029 | B39: 察隅县 | C39: 2022 | D39: 察隅县下察隅镇卡地村茶园提升改造建设项目 | E39: 402.64434 | F39: =SUMIF('附件5-2'!$A$4:$A$336,A39,'附件5-2'!$I$4:$I$336) -> 9 | G39: 201.25 | H39: 168.73937 | I39: 集体资产 | J39: 农村集体经济组织 | K39: 林芝市察隅县下察隅镇卡地村股份经济合作社 | M39: 林芝市察隅县下察隅镇卡地村股份经济合作社 | N39: 西藏自治区林芝市察隅县下察隅镇卡地村村民委员会 | O39: 林芝市察隅县下察隅镇卡地村股份经济合作社
A40: 540425202012020 | B40: 察隅县 | C40: 2020 | D40: 察隅县下察隅镇卡地村第二期茶叶种植项目 | E40: 176.3802 | F40: =SUMIF('附件5-2'!$A$4:$A$336,A40,'附件5-2'!$I$4:$I$336) -> 266.46 | G40: 40.59 | H40: 23.001 | I40: 集体资产 | J40: 农村集体经济组织 | K40: 林芝市察隅县下察隅镇卡地村股份经济合作社 | L40: 西藏自治区林芝市察隅县下察隅镇卡地村股份经济合作社 | M40: 林芝市察隅县下察隅镇卡地村股份经济合作社 | N40: 西藏自治区林芝市察隅县下察隅镇卡地村村民委员会 | O40: 林芝市察隅县下察隅镇卡地村股份经济合作社
...

Sheet 附件5-2
A1: 西藏自治区察隅县帮扶产业项目资产明细表 （截至2026年6月20日数据）
A2: 项目编号 | B2: 项目县区 | C2: 资产编号 | D2: 资产名称 | E2: 构（购）建时间 （必填年月） | F2: 坐落或置放 位置 | G2: 资产 型号 | H2: 预计使用年限（自构建时间起预计能够使用的年限数） | I2: 资产 个数 | J2: 资产 原值（元） | K2: 资产累计 折旧 （摊销）（元） | L2: 资产 净值（元） | M2: 资产形态 | N2: 具体形态 | O2: 资产 属性 | P2: 资产状态 | Q2: 资产使用情况 | R2: 资产 类别 | S2: 资产 类别 | T2: 经营性资产运营情况 | U2: 资产所有权主体名称 | V2: 备注
A3: 填表说明：与表3项目编号一致 | C3: 根据指南编码规则对资产进行编号 | D3: 按形成的具体资产名称填写，不同资产应分行填写 | E3: 例：2018.01 | H3: 例：10（即为该资产预计可使用时间为10年） | J3: 保留2位小数 | K3: 统计时间为截止2024年12月31日 （权益类资产、消耗性生物资产、公益性生物资产不填） 保留2位小数 | L3: 统计时间为截止2024年12月31日 保留2位小数 | M3: 在“固定资产、生物资产（含消耗性生物资产、生产性生物资产、公益性生物资产）、权益类资产、其他资产”中选择 | N3: 在“房屋建筑物、构筑物、机器设备、车辆、办公用具家具、牲畜（禽）、林木、股权资产、债权资产、低值易耗品、无形资产”中选择 | O3: 在“国有资产、集体资产”中选择 | P3: 在“正常、损坏、损毁”中选择 | Q3: 根据实际情况填写“在用/不在用” | R3: 在“自用、出租、存栏、在培、已消耗、已出售、已死亡、闲置、损毁、拆除、待维修、盘亏等”中选择 | S3: 在“经营性资产、公益性资产”中选择 | T3: 在“正常、低效、闲置”中选择
A4: 540425201916012 | B4: 察隅县 | C4: 54042520191601210001 | D4: 联栋温室大棚 | E4: 43466 | F4: 学尼村 | G4: 个 | H4: 20 | I4: 1 | J4: 1855000 | K4: 556500 | L4: 1298500 | M4: 固定资产 | N4: 构筑物 | O4: 集体资产 | P4: 正常 | Q4: 在用 | R4: 出租 | S4: 经营性资产 | T4: 正常 | U4: 林芝市察隅县竹瓦根镇学尼村股份经济合作社
A5: 540425201916012 | B5: 察隅县 | C5: 54042520191601210002 | D5: 联栋温室大棚 | E5: 43466 | F5: 学尼村 | G5: 个 | H5: 20 | I5: 1 | J5: 1855000 | K5: 556500 | L5: 1298500 | M5: 固定资产 | N5: 构筑物 | O5: 集体资产 | P5: 正常 | Q5: 在用 | R5: 出租 | S5: 经营性资产 | T5: 正常 | U5: 林芝市察隅县竹瓦根镇学尼村股份经济合作社
A6: 540425201916012 | B6: 察隅县 | C6: 54042520191601210003 | D6: 联栋温室大棚 | E6: 43466 | F6: 学尼村 | G6: 个 | H6: 20 | I6: 1 | J6: 1855000 | K6: 556500 | L6: 1298500 | M6: 固定资产 | N6: 构筑物 | O6: 集体资产 | P6: 正常 | Q6: 在用 | R6: 出租 | S6: 经营性资产 | T6: 正常 | U6: 林芝市察隅县竹瓦根镇学尼村股份经济合作社
A7: 540425201916012 | B7: 察隅县 | C7: 54042520191601210004 | D7: 联栋温室大棚 | E7: 43466 | F7: 学尼村 | G7: 个 | H7: 20 | I7: 1 | J7: 1855000 | K7: 556500 | L7: 1298500 | M7: 固定资产 | N7: 构筑物 | O7: 集体资产 | P7: 正常 | Q7: 在用 | R7: 出租 | S7: 经营性资产 | T7: 正常 | U7: 林芝市察隅县竹瓦根镇学尼村股份经济合作社
A8: 540425202116013 | B8: 察隅县 | C8: 54042520211601310001 | D8: 温室大棚 | E8: 44562 | F8: 学尼村 | G8: 个 | H8: 20 | I8: 1 | J8: 1238530.2 | K8: 185779.53 | L8: 1052750.6 | M8: 固定资产 | N8: 构筑物 | O8: 集体资产 | P8: 正常 | Q8: 在用 | R8: 闲置 | S8: 经营性资产 | T8: 正常 | U8: 林芝市察隅县竹瓦根镇学尼村股份经济合作社
A9: 540425202116013 | B9: 察隅县 | C9: 54042520211601310002 | D9: 温室大棚 | E9: 44562 | F9: 学尼村 | G9: 个 | H9: 20 | I9: 1 | J9: 1238530.2 | K9: 185779.53 | L9: 1052750.6 | M9: 固定资产 | N9: 构筑物 | O9: 集体资产 | P9: 正常 | Q9: 在用 | R9: 闲置 | S9: 经营性资产 | T9: 正常 | U9: 林芝市察隅县竹瓦根镇学尼村股份经济合作社
A10: 540425202116013 | B10: 察隅县 | C10: 54042520211601310003 | D10: 温室大棚 | E10: 44562 | F10: 学尼村 | G10: 个 | H10: 20 | I10: 1 | J10: 1238530.2 | K10: 185779.53 | L10: 1052750.6 | M10: 固定资产 | N10: 构筑物 | O10: 集体资产 | P10: 正常 | Q10: 在用 | R10: 闲置 | S10: 经营性资产 | T10: 正常 | U10: 林芝市察隅县竹瓦根镇学尼村股份经济合作社
A11: 540425201908006 | B11: 察隅县 | C11: 54042520190800610001 | D11: 鸡舍 | E11: 43647 | F11: 空档村 | G11: 栋 | H11: 20 | I11: 1 | J11: 228983.33 | K11: 62970.42 | L11: 166012.91 | M11: 固定资产 | N11: 房屋建筑物 | O11: 集体资产 | P11: 正常 | Q11: 在用 | R11: 闲置 | S11: 经营性资产 | T11: 正常 | U11: 林芝市察隅县竹瓦根镇空档村股份经济合作社
A12: 540425201908006 | B12: 察隅县 | C12: 54042520190800610002 | D12: 鸡舍 | E12: 43647 | F12: 空档村 | G12: 栋 | H12: 20 | I12: 1 | J12: 228983.33 | K12: 62970.42 | L12: 166012.91 | M12: 固定资产 | N12: 房屋建筑物 | O12: 集体资产 | P12: 正常 | Q12: 在用 | R12: 闲置 | S12: 经营性资产 | T12: 正常 | U12: 林芝市察隅县竹瓦根镇空档村股份经济合作社
A13: 540425201908006 | B13: 察隅县 | C13: 54042520190800610003 | D13: 消毒池 | E13: 43647 | F13: 空档村 | G13: 座 | H13: 20 | I13: 1 | J13: 132533.34 | K13: 36446.67 | L13: 96086.67 | M13: 固定资产 | N13: 房屋建筑物 | O13: 集体资产 | P13: 正常 | Q13: 在用 | R13: 闲置 | S13: 经营性资产 | T13: 正常 | U13: 林芝市察隅县竹瓦根镇空档村股份经济合作社
A14: 540425202019028 | B14: 察隅县 | C14: 54042520201902810001 | D14: 10吨水处理系统 | E14: 43831 | F14: 嘎巴村 | G14: 套 | H14: 10 | I14: 1 | J14: 349000 | K14: 174500 | L14: 174500 | M14: 固定资产 | N14: 机器设备 | O14: 国有资产 | P14: 正常 | Q14: 在用 | R14: 闲置 | S14: 经营性资产 | T14: 正常 | U14: 察隅县雪巅啤酒有限公司
A15: 540425202019028 | B15: 察隅县 | C15: 54042520201902810002 | D15: 粉碎系统 | E15: 43831 | F15: 嘎巴村 | G15: 套 | H15: 10 | I15: 1 | J15: 88000 | K15: 44000 | L15: 44000 | M15: 固定资产 | N15: 机器设备 | O15: 国有资产 | P15: 正常 | Q15: 在用 | R15: 闲置 | S15: 经营性资产 | T15: 正常 | U15: 察隅县雪巅啤酒有限公司
... A115: 540425201918003 | B115: 察隅县 | C115: 54042520191800310007 | D115: 大门 | E115: 44105 | F115: 竹瓦根镇 | G115: 栋 | H115: 20 | I115: 1 | J115: 216400 | K115: 45985 | L115: 170415 | M115: 固定资产 | N115: 房屋建筑物 | O115: 国有资产 | P115: 正常 | Q115: 在用 | R115: 出租 | S115: 经营性资产 | T115: 正常 | U115: 察隅县扶贫开发投资有限公司
A116: 540425202204009 | B116: 察隅县 | C116: 54042520220400910001 | D116: 通电工程 | E116: 45078 | F116: 罗马村 | G116: 套 | H116: 20 | I116: 1 | J116: 942468.4 | K116: 74612.08 | L116: 867856.32 | M116: 固定资产 | N116: 构筑物 | O116: 集体资产 | P116: 正常 | Q116: 在用 | R116: 出租 | S116: 公益性资产 | U116: 林芝市察隅县古玉乡罗马村股份经济合作社
A117: 540425201907012 | B117: 察隅县 | C117: 54042520190701210001 | D117: 猪舍 | E117: 43952 | F117: 沙琼村 | G117: 栋 | H117: 20 | I117: 1 | J117: 143333.33 | K117: 33444.44 | L117: 109888.89 | M117: 固定资产 | N117: 房屋建筑物 | O117: 集体资产 | P117: 正常 | Q117: 在用 | R117: 出租 | S117: 经营性资产 | T117: 正常 | U117: 林芝市察隅县下察隅镇沙琼村股份经济合作社
A118: 540425201907012 | B118: 察隅县 | C118: 54042520190701210002 | D118: 饲料库房 | E118: 43952 | F118: 沙琼村 | G118: 栋 | H118: 20 | I118: 1 | J118: 55000 | K118: 12833.33 | L118: 42166.67 | M118: 固定资产 | N118: 房屋建筑物 | O118: 集体资产 | P118: 正常 | Q118: 在用 | R118: 出租 | S118: 经营性资产 | T118: 正常 | U118: 林芝市察隅县下察隅镇沙琼村股份经济合作社
A119: 540425201907012 | B119: 察隅县 | C119: 54042520190701210003 | D119: 饲料加工房 | E119: 43952 | F119: 沙琼村 | G119: 栋 | H119: 20 | I119: 1 | J119: 36666.67 | K119: 8555.56 | L119: 28111.11 | M119: 固定资产 | N119: 房屋建筑物 | O119: 集体资产 | P119: 正常 | Q119: 在用 | R119: 出租 | S119: 经营性资产 | T119: 正常 | U119: 林芝市察隅县下察隅镇沙琼村股份经济合作社
A120: 540425201907012 | B120: 察隅县 | C120: 54042520190701210004 | D120: 蓄水池 | E120: 43952 | F120: 沙琼村 | G120: 座 | H120: 20 | I120: 1 | J120: 2700 | K120: 630 | L120: 2070 | M120: 固定资产 | N120: 房屋建筑物 | O120: 集体资产 | P120: 正常 | Q120: 在用 | R120: 出租 | S120: 经营性资产 | T120: 正常 | U120: 林芝市察隅县下察隅镇沙琼村股份经济合作社
A121: 540425201907012 | B121: 察隅县 | C121: 54042520190701210005 | D121: 饲料加工机 | E121: 43952 | F121: 沙琼村 | G121: 台 | H121: 5 | I121: 1 | J121: 10000 | K121: 9333.33 | L121: 666.67 | M121: 固定资产 | N121: 机器设备 | O121: 集体资产 | P121: 正常 | Q121: 在用 | R121: 出租 | S121: 经营性资产 | T121: 正常 | U121: 林芝市察隅县下察隅镇沙琼村股份经济合作社
A122: 540425201907012 | B122: 察隅县 | C122: 54042520190701210006 | D122: 柴油发电机 | E122: 43952 | F122: 沙琼村 | G122: 台 | H122: 5 | I122: 1 | J122: 7800 | K122: 7280 | L122: 520 | M122: 固定资产 | N122: 机器设备 | O122: 集体资产 | P122: 损毁 | Q122: 不在用 | R122: 损毁 | S122: 经营性资产 | T122: 闲置 | U122: 林芝市察隅县下察隅镇沙琼村股份经济合作社
A123: 540425201907012 | B123: 察隅县 | C123: 54042520190701220007 | D123: 猪 | E123: 43952 | F123: 沙琼村 | G123: 只 | H123: 3 | I123: 63 | J123: 244500 | K123: 244500 | L123: 0 | M123: 生物资产 | N123: 牲畜（禽） | O123: 集体资产 | P123: 损毁 | Q123: 不在用 | R123: 已死亡 | S123: 经营性资产 | T123: 闲置 | U123: 林芝市察隅县下察隅镇沙琼村股份经济合作社
A124: 540425201715001 | B124: 察隅县 | C124: 54042520171500110001 | D124: 管理培训中心 | E124: 43252 | F124: 夏尼村 | G124: 栋 | H124: 20 | I124: 1 | J124: 850759.99 | K124: 280041.83 | L124: 570718.16 | M124: 固定资产 | N124: 房屋建筑物 | O124: 集体资产 | P124: 正常 | Q124: 在用 | R124: 出租 | S124: 经营性资产 | T124: 正常 | U124: 林芝市察隅县下察隅镇夏尼村股份经济合作社
A125: 540425201715001 | B125: 察隅县 | C125: 54042520171500110002 | D125: 猕猴桃架桩 | E125: 43252 | F125: 夏尼村 | G125: 套 | H125: 10 | I125: 1 | J125: 235300 | K125: 154905.83 | L125: 80394.17 | M125: 固定资产 | N125: 构筑物 | O125: 集体资产 | P125: 正常 | Q125: 在用 | R125: 出租 | S125: 经营性资产 | T125: 正常 | U125: 林芝市察隅县下察隅镇夏尼村股份经济合作社
A126: 540425201715001 | B126: 察隅县 | C126: 54042520171500110003 | D126: 铁丝网 | E126: 43252 | F126: 夏尼村 | G126: 套 | H126: 10 | I126: 1 | J126: 120000 | K126: 79000 | L126: 41000 | M126: 固定资产 | N126: 构筑物 | O126: 集体资产 | P126: 正常 | Q126: 在用 | R126: 出租 | S126: 经营性资产 | T126: 正常 | U126: 林芝市察隅县下察隅镇夏尼村股份经济合作社
A127: 540425201715001 | B127: 察隅县 | C127: 54042520171500120004 | D127: 猕猴桃苗木 | E127: 43252 | F127: 夏尼村 | G127: 株 | H127: 10 | I127: 6000 | J127: 54000 | K127: 35550 | L127: 18450 | M127: 生物资产 | N127: 林木 | O127: 集体资产 | P127: 正常 | Q127: 在用 | R127: 出租 | S127: 经营性资产 | T127: 正常 | U127: 林芝市察隅县下察隅镇夏尼村股份经济合作社
A128: 540425202115006 | B128: 察隅县 | C128: 54042520211500620001 | D128: 猕猴桃 | E128: 44562 | F128: 夏尼村 | G128: 亩 | H128: 10 | I128: 100 | J128: 2294800 | K128: 688440 | L128: 1606360 | M128: 生物资产 | N128: 林木 | O128: 集体资产 | P128: 正常 | Q128: 在用 | R128: 出租 | S128: 经营性资产 | T128: 正常 | U128: 林芝市察隅县下察隅镇夏尼村股份经济合作社 | V128: 项目原种植数量无数据，期间又有补种等，无法核实项目原始株树
A129: 540425202115004 | B129: 察隅县 | C129: 54042520211500410001 | D129: 青石板步道 | E129: 44501 | F129: 夏尼村 | G129: 600米 | H129: 10 | I129: 1 | J129: 115200 | K129: 36480 | L129: 78720 | M129: 固定资产 | N129: 构筑物 | O129: 集体资产 | P129: 正常 | Q129: 在用 | R129: 出租 | S129: 公益性资产 | U129: 林芝市察隅县下察隅镇夏尼村股份经济合作社
